[32mINFO    [0m pytest_operator.plugin:plugin.py:862 Model status:

Model  Controller           Cloud/Region         Version  SLA          Timestamp
test   localhost-localhost  localhost/localhost  3.4.4    unsupported  01:55:29Z

App                  Version  Status  Scale  Charm                Channel      Rev  Exposed  Message
postgresql           14.12    active      3  postgresql           14/edge      471  no       
postgresql-test-app           active      1  postgresql-test-app  latest/edge  242  no       

Unit                    Workload  Agent  Machine  Public address  Ports     Message
postgresql-test-app/0*  active    idle   3        10.117.218.66             
postgresql/0            active    idle   0        10.117.218.132  5432/tcp  
postgresql/1            active    idle   1        10.117.218.35   5432/tcp  
postgresql/2*           active    idle   2        10.117.218.88   5432/tcp  Primary

Machine  State    Address         Inst id        Base          AZ  Message
0        started  10.117.218.132  juju-20b572-0  ubuntu@22.04      Running
1        started  10.117.218.35   juju-20b572-1  ubuntu@22.04      Running
2        started  10.117.218.88   juju-20b572-2  ubuntu@22.04      Running
3        started  10.117.218.66   juju-20b572-3  ubuntu@22.04      Running

[32mINFO    [0m pytest_operator.plugin:plugin.py:868 Juju error logs:

machine-2: 01:43:03 ERROR juju.worker.dependency "lxd-container-provisioner" manifold worker returned unexpected error: container types not yet available
machine-2: 01:43:03 ERROR juju.worker.dependency "kvm-container-provisioner" manifold worker returned unexpected error: container types not yet available
unit-postgresql-2: 01:43:03 ERROR juju.worker.meterstatus error running "meter-status-changed": charm missing from disk
machine-1: 01:43:03 ERROR juju.worker.dependency "kvm-container-provisioner" manifold worker returned unexpected error: container types not yet available
machine-1: 01:43:03 ERROR juju.worker.dependency "lxd-container-provisioner" manifold worker returned unexpected error: container types not yet available
unit-postgresql-1: 01:43:03 ERROR juju.worker.meterstatus error running "meter-status-changed": charm missing from disk
machine-3: 01:43:08 ERROR juju.worker.dependency "lxd-container-provisioner" manifold worker returned unexpected error: container types not yet available
machine-3: 01:43:08 ERROR juju.worker.dependency "kvm-container-provisioner" manifold worker returned unexpected error: container types not yet available
unit-postgresql-test-app-0: 01:43:08 ERROR juju.worker.meterstatus error running "meter-status-changed": charm missing from disk
machine-0: 01:43:09 ERROR juju.worker.dependency "lxd-container-provisioner" manifold worker returned unexpected error: container types not yet available
machine-0: 01:43:09 ERROR juju.worker.dependency "kvm-container-provisioner" manifold worker returned unexpected error: container types not yet available
unit-postgresql-0: 01:43:09 ERROR juju.worker.meterstatus error running "meter-status-changed": charm missing from disk
unit-postgresql-test-app-0: 01:50:26 ERROR unit.postgresql-test-app/0.juju-log Uncaught exception while in charm code:
Traceback (most recent call last):
  File "/var/lib/juju/agents/unit-postgresql-test-app-0/charm/./src/charm.py", line 538, in <module>
    main(ApplicationCharm)
  File "/var/lib/juju/agents/unit-postgresql-test-app-0/charm/venv/ops/main.py", line 553, in main
    manager.run()
  File "/var/lib/juju/agents/unit-postgresql-test-app-0/charm/venv/ops/main.py", line 529, in run
    self._emit()
  File "/var/lib/juju/agents/unit-postgresql-test-app-0/charm/venv/ops/main.py", line 518, in _emit
    _emit_charm_event(self.charm, self.dispatcher.event_name, self._juju_context)
  File "/var/lib/juju/agents/unit-postgresql-test-app-0/charm/venv/ops/main.py", line 139, in _emit_charm_event
    event_to_emit.emit(*args, **kwargs)
  File "/var/lib/juju/agents/unit-postgresql-test-app-0/charm/venv/ops/framework.py", line 347, in emit
    framework._emit(event)
  File "/var/lib/juju/agents/unit-postgresql-test-app-0/charm/venv/ops/framework.py", line 853, in _emit
    self._reemit(event_path)
  File "/var/lib/juju/agents/unit-postgresql-test-app-0/charm/venv/ops/framework.py", line 943, in _reemit
    custom_handler(event)
  File "/var/lib/juju/agents/unit-postgresql-test-app-0/charm/./src/charm.py", line 289, in _on_clear_continuous_writes_action
    if self._connection_string is None:
  File "/var/lib/juju/agents/unit-postgresql-test-app-0/charm/./src/charm.py", line 259, in _connection_string
    data = list(self.first_database.fetch_relation_data().values())[0]
AttributeError: 'ApplicationCharm' object has no attribute 'first_database'
unit-postgresql-test-app-0: 01:50:30 ERROR unit.postgresql-test-app/0.juju-log Uncaught exception while in charm code:
Traceback (most recent call last):
  File "/var/lib/juju/agents/unit-postgresql-test-app-0/charm/./src/charm.py", line 538, in <module>
    main(ApplicationCharm)
  File "/var/lib/juju/agents/unit-postgresql-test-app-0/charm/venv/ops/main.py", line 553, in main
    manager.run()
  File "/var/lib/juju/agents/unit-postgresql-test-app-0/charm/venv/ops/main.py", line 529, in run
    self._emit()
  File "/var/lib/juju/agents/unit-postgresql-test-app-0/charm/venv/ops/main.py", line 518, in _emit
    _emit_charm_event(self.charm, self.dispatcher.event_name, self._juju_context)
  File "/var/lib/juju/agents/unit-postgresql-test-app-0/charm/venv/ops/main.py", line 139, in _emit_charm_event
    event_to_emit.emit(*args, **kwargs)
  File "/var/lib/juju/agents/unit-postgresql-test-app-0/charm/venv/ops/framework.py", line 347, in emit
    framework._emit(event)
  File "/var/lib/juju/agents/unit-postgresql-test-app-0/charm/venv/ops/framework.py", line 853, in _emit
    self._reemit(event_path)
  File "/var/lib/juju/agents/unit-postgresql-test-app-0/charm/venv/ops/framework.py", line 943, in _reemit
    custom_handler(event)
  File "/var/lib/juju/agents/unit-postgresql-test-app-0/charm/./src/charm.py", line 289, in _on_clear_continuous_writes_action
    if self._connection_string is None:
  File "/var/lib/juju/agents/unit-postgresql-test-app-0/charm/./src/charm.py", line 259, in _connection_string
    data = list(self.first_database.fetch_relation_data().values())[0]
AttributeError: 'ApplicationCharm' object has no attribute 'first_database'
unit-postgresql-test-app-0: 01:50:34 ERROR unit.postgresql-test-app/0.juju-log Uncaught exception while in charm code:
Traceback (most recent call last):
  File "/var/lib/juju/agents/unit-postgresql-test-app-0/charm/./src/charm.py", line 538, in <module>
    main(ApplicationCharm)
  File "/var/lib/juju/agents/unit-postgresql-test-app-0/charm/venv/ops/main.py", line 553, in main
    manager.run()
  File "/var/lib/juju/agents/unit-postgresql-test-app-0/charm/venv/ops/main.py", line 529, in run
    self._emit()
  File "/var/lib/juju/agents/unit-postgresql-test-app-0/charm/venv/ops/main.py", line 518, in _emit
    _emit_charm_event(self.charm, self.dispatcher.event_name, self._juju_context)
  File "/var/lib/juju/agents/unit-postgresql-test-app-0/charm/venv/ops/main.py", line 139, in _emit_charm_event
    event_to_emit.emit(*args, **kwargs)
  File "/var/lib/juju/agents/unit-postgresql-test-app-0/charm/venv/ops/framework.py", line 347, in emit
    framework._emit(event)
  File "/var/lib/juju/agents/unit-postgresql-test-app-0/charm/venv/ops/framework.py", line 853, in _emit
    self._reemit(event_path)
  File "/var/lib/juju/agents/unit-postgresql-test-app-0/charm/venv/ops/framework.py", line 943, in _reemit
    custom_handler(event)
  File "/var/lib/juju/agents/unit-postgresql-test-app-0/charm/./src/charm.py", line 289, in _on_clear_continuous_writes_action
    if self._connection_string is None:
  File "/var/lib/juju/agents/unit-postgresql-test-app-0/charm/./src/charm.py", line 259, in _connection_string
    data = list(self.first_database.fetch_relation_data().values())[0]
AttributeError: 'ApplicationCharm' object has no attribute 'first_database'
unit-postgresql-test-app-0: 01:50:38 ERROR unit.postgresql-test-app/0.juju-log Uncaught exception while in charm code:
Traceback (most recent call last):
  File "/var/lib/juju/agents/unit-postgresql-test-app-0/charm/./src/charm.py", line 538, in <module>
    main(ApplicationCharm)
  File "/var/lib/juju/agents/unit-postgresql-test-app-0/charm/venv/ops/main.py", line 553, in main
    manager.run()
  File "/var/lib/juju/agents/unit-postgresql-test-app-0/charm/venv/ops/main.py", line 529, in run
    self._emit()
  File "/var/lib/juju/agents/unit-postgresql-test-app-0/charm/venv/ops/main.py", line 518, in _emit
    _emit_charm_event(self.charm, self.dispatcher.event_name, self._juju_context)
  File "/var/lib/juju/agents/unit-postgresql-test-app-0/charm/venv/ops/main.py", line 139, in _emit_charm_event
    event_to_emit.emit(*args, **kwargs)
  File "/var/lib/juju/agents/unit-postgresql-test-app-0/charm/venv/ops/framework.py", line 347, in emit
    framework._emit(event)
  File "/var/lib/juju/agents/unit-postgresql-test-app-0/charm/venv/ops/framework.py", line 853, in _emit
    self._reemit(event_path)
  File "/var/lib/juju/agents/unit-postgresql-test-app-0/charm/venv/ops/framework.py", line 943, in _reemit
    custom_handler(event)
  File "/var/lib/juju/agents/unit-postgresql-test-app-0/charm/./src/charm.py", line 289, in _on_clear_continuous_writes_action
    if self._connection_string is None:
  File "/var/lib/juju/agents/unit-postgresql-test-app-0/charm/./src/charm.py", line 259, in _connection_string
    data = list(self.first_database.fetch_relation_data().values())[0]
AttributeError: 'ApplicationCharm' object has no attribute 'first_database'
unit-postgresql-test-app-0: 01:50:42 ERROR unit.postgresql-test-app/0.juju-log Uncaught exception while in charm code:
Traceback (most recent call last):
  File "/var/lib/juju/agents/unit-postgresql-test-app-0/charm/./src/charm.py", line 538, in <module>
    main(ApplicationCharm)
  File "/var/lib/juju/agents/unit-postgresql-test-app-0/charm/venv/ops/main.py", line 553, in main
    manager.run()
  File "/var/lib/juju/agents/unit-postgresql-test-app-0/charm/venv/ops/main.py", line 529, in run
    self._emit()
  File "/var/lib/juju/agents/unit-postgresql-test-app-0/charm/venv/ops/main.py", line 518, in _emit
    _emit_charm_event(self.charm, self.dispatcher.event_name, self._juju_context)
  File "/var/lib/juju/agents/unit-postgresql-test-app-0/charm/venv/ops/main.py", line 139, in _emit_charm_event
    event_to_emit.emit(*args, **kwargs)
  File "/var/lib/juju/agents/unit-postgresql-test-app-0/charm/venv/ops/framework.py", line 347, in emit
    framework._emit(event)
  File "/var/lib/juju/agents/unit-postgresql-test-app-0/charm/venv/ops/framework.py", line 853, in _emit
    self._reemit(event_path)
  File "/var/lib/juju/agents/unit-postgresql-test-app-0/charm/venv/ops/framework.py", line 943, in _reemit
    custom_handler(event)
  File "/var/lib/juju/agents/unit-postgresql-test-app-0/charm/./src/charm.py", line 289, in _on_clear_continuous_writes_action
    if self._connection_string is None:
  File "/var/lib/juju/agents/unit-postgresql-test-app-0/charm/./src/charm.py", line 259, in _connection_string
    data = list(self.first_database.fetch_relation_data().values())[0]
AttributeError: 'ApplicationCharm' object has no attribute 'first_database'
unit-postgresql-test-app-0: 01:50:46 ERROR unit.postgresql-test-app/0.juju-log Uncaught exception while in charm code:
Traceback (most recent call last):
  File "/var/lib/juju/agents/unit-postgresql-test-app-0/charm/./src/charm.py", line 538, in <module>
    main(ApplicationCharm)
  File "/var/lib/juju/agents/unit-postgresql-test-app-0/charm/venv/ops/main.py", line 553, in main
    manager.run()
  File "/var/lib/juju/agents/unit-postgresql-test-app-0/charm/venv/ops/main.py", line 529, in run
    self._emit()
  File "/var/lib/juju/agents/unit-postgresql-test-app-0/charm/venv/ops/main.py", line 518, in _emit
    _emit_charm_event(self.charm, self.dispatcher.event_name, self._juju_context)
  File "/var/lib/juju/agents/unit-postgresql-test-app-0/charm/venv/ops/main.py", line 139, in _emit_charm_event
    event_to_emit.emit(*args, **kwargs)
  File "/var/lib/juju/agents/unit-postgresql-test-app-0/charm/venv/ops/framework.py", line 347, in emit
    framework._emit(event)
  File "/var/lib/juju/agents/unit-postgresql-test-app-0/charm/venv/ops/framework.py", line 853, in _emit
    self._reemit(event_path)
  File "/var/lib/juju/agents/unit-postgresql-test-app-0/charm/venv/ops/framework.py", line 943, in _reemit
    custom_handler(event)
  File "/var/lib/juju/agents/unit-postgresql-test-app-0/charm/./src/charm.py", line 289, in _on_clear_continuous_writes_action
    if self._connection_string is None:
  File "/var/lib/juju/agents/unit-postgresql-test-app-0/charm/./src/charm.py", line 259, in _connection_string
    data = list(self.first_database.fetch_relation_data().values())[0]
AttributeError: 'ApplicationCharm' object has no attribute 'first_database'
unit-postgresql-test-app-0: 01:50:50 ERROR unit.postgresql-test-app/0.juju-log Uncaught exception while in charm code:
Traceback (most recent call last):
  File "/var/lib/juju/agents/unit-postgresql-test-app-0/charm/./src/charm.py", line 538, in <module>
    main(ApplicationCharm)
  File "/var/lib/juju/agents/unit-postgresql-test-app-0/charm/venv/ops/main.py", line 553, in main
    manager.run()
  File "/var/lib/juju/agents/unit-postgresql-test-app-0/charm/venv/ops/main.py", line 529, in run
    self._emit()
  File "/var/lib/juju/agents/unit-postgresql-test-app-0/charm/venv/ops/main.py", line 518, in _emit
    _emit_charm_event(self.charm, self.dispatcher.event_name, self._juju_context)
  File "/var/lib/juju/agents/unit-postgresql-test-app-0/charm/venv/ops/main.py", line 139, in _emit_charm_event
    event_to_emit.emit(*args, **kwargs)
  File "/var/lib/juju/agents/unit-postgresql-test-app-0/charm/venv/ops/framework.py", line 347, in emit
    framework._emit(event)
  File "/var/lib/juju/agents/unit-postgresql-test-app-0/charm/venv/ops/framework.py", line 853, in _emit
    self._reemit(event_path)
  File "/var/lib/juju/agents/unit-postgresql-test-app-0/charm/venv/ops/framework.py", line 943, in _reemit
    custom_handler(event)
  File "/var/lib/juju/agents/unit-postgresql-test-app-0/charm/./src/charm.py", line 289, in _on_clear_continuous_writes_action
    if self._connection_string is None:
  File "/var/lib/juju/agents/unit-postgresql-test-app-0/charm/./src/charm.py", line 259, in _connection_string
    data = list(self.first_database.fetch_relation_data().values())[0]
AttributeError: 'ApplicationCharm' object has no attribute 'first_database'
unit-postgresql-test-app-0: 01:50:54 ERROR unit.postgresql-test-app/0.juju-log Uncaught exception while in charm code:
Traceback (most recent call last):
  File "/var/lib/juju/agents/unit-postgresql-test-app-0/charm/./src/charm.py", line 538, in <module>
    main(ApplicationCharm)
  File "/var/lib/juju/agents/unit-postgresql-test-app-0/charm/venv/ops/main.py", line 553, in main
    manager.run()
  File "/var/lib/juju/agents/unit-postgresql-test-app-0/charm/venv/ops/main.py", line 529, in run
    self._emit()
  File "/var/lib/juju/agents/unit-postgresql-test-app-0/charm/venv/ops/main.py", line 518, in _emit
    _emit_charm_event(self.charm, self.dispatcher.event_name, self._juju_context)
  File "/var/lib/juju/agents/unit-postgresql-test-app-0/charm/venv/ops/main.py", line 139, in _emit_charm_event
    event_to_emit.emit(*args, **kwargs)
  File "/var/lib/juju/agents/unit-postgresql-test-app-0/charm/venv/ops/framework.py", line 347, in emit
    framework._emit(event)
  File "/var/lib/juju/agents/unit-postgresql-test-app-0/charm/venv/ops/framework.py", line 853, in _emit
    self._reemit(event_path)
  File "/var/lib/juju/agents/unit-postgresql-test-app-0/charm/venv/ops/framework.py", line 943, in _reemit
    custom_handler(event)
  File "/var/lib/juju/agents/unit-postgresql-test-app-0/charm/./src/charm.py", line 289, in _on_clear_continuous_writes_action
    if self._connection_string is None:
  File "/var/lib/juju/agents/unit-postgresql-test-app-0/charm/./src/charm.py", line 259, in _connection_string
    data = list(self.first_database.fetch_relation_data().values())[0]
AttributeError: 'ApplicationCharm' object has no attribute 'first_database'
unit-postgresql-test-app-0: 01:50:58 ERROR unit.postgresql-test-app/0.juju-log Uncaught exception while in charm code:
Traceback (most recent call last):
  File "/var/lib/juju/agents/unit-postgresql-test-app-0/charm/./src/charm.py", line 538, in <module>
    main(ApplicationCharm)
  File "/var/lib/juju/agents/unit-postgresql-test-app-0/charm/venv/ops/main.py", line 553, in main
    manager.run()
  File "/var/lib/juju/agents/unit-postgresql-test-app-0/charm/venv/ops/main.py", line 529, in run
    self._emit()
  File "/var/lib/juju/agents/unit-postgresql-test-app-0/charm/venv/ops/main.py", line 518, in _emit
    _emit_charm_event(self.charm, self.dispatcher.event_name, self._juju_context)
  File "/var/lib/juju/agents/unit-postgresql-test-app-0/charm/venv/ops/main.py", line 139, in _emit_charm_event
    event_to_emit.emit(*args, **kwargs)
  File "/var/lib/juju/agents/unit-postgresql-test-app-0/charm/venv/ops/framework.py", line 347, in emit
    framework._emit(event)
  File "/var/lib/juju/agents/unit-postgresql-test-app-0/charm/venv/ops/framework.py", line 853, in _emit
    self._reemit(event_path)
  File "/var/lib/juju/agents/unit-postgresql-test-app-0/charm/venv/ops/framework.py", line 943, in _reemit
    custom_handler(event)
  File "/var/lib/juju/agents/unit-postgresql-test-app-0/charm/./src/charm.py", line 289, in _on_clear_continuous_writes_action
    if self._connection_string is None:
  File "/var/lib/juju/agents/unit-postgresql-test-app-0/charm/./src/charm.py", line 259, in _connection_string
    data = list(self.first_database.fetch_relation_data().values())[0]
AttributeError: 'ApplicationCharm' object has no attribute 'first_database'
unit-postgresql-test-app-0: 01:51:02 ERROR unit.postgresql-test-app/0.juju-log Uncaught exception while in charm code:
Traceback (most recent call last):
  File "/var/lib/juju/agents/unit-postgresql-test-app-0/charm/./src/charm.py", line 538, in <module>
    main(ApplicationCharm)
  File "/var/lib/juju/agents/unit-postgresql-test-app-0/charm/venv/ops/main.py", line 553, in main
    manager.run()
  File "/var/lib/juju/agents/unit-postgresql-test-app-0/charm/venv/ops/main.py", line 529, in run
    self._emit()
  File "/var/lib/juju/agents/unit-postgresql-test-app-0/charm/venv/ops/main.py", line 518, in _emit
    _emit_charm_event(self.charm, self.dispatcher.event_name, self._juju_context)
  File "/var/lib/juju/agents/unit-postgresql-test-app-0/charm/venv/ops/main.py", line 139, in _emit_charm_event
    event_to_emit.emit(*args, **kwargs)
  File "/var/lib/juju/agents/unit-postgresql-test-app-0/charm/venv/ops/framework.py", line 347, in emit
    framework._emit(event)
  File "/var/lib/juju/agents/unit-postgresql-test-app-0/charm/venv/ops/framework.py", line 853, in _emit
    self._reemit(event_path)
  File "/var/lib/juju/agents/unit-postgresql-test-app-0/charm/venv/ops/framework.py", line 943, in _reemit
    custom_handler(event)
  File "/var/lib/juju/agents/unit-postgresql-test-app-0/charm/./src/charm.py", line 289, in _on_clear_continuous_writes_action
    if self._connection_string is None:
  File "/var/lib/juju/agents/unit-postgresql-test-app-0/charm/./src/charm.py", line 259, in _connection_string
    data = list(self.first_database.fetch_relation_data().values())[0]
AttributeError: 'ApplicationCharm' object has no attribute 'first_database'
unit-postgresql-test-app-0: 01:51:06 ERROR unit.postgresql-test-app/0.juju-log Uncaught exception while in charm code:
Traceback (most recent call last):
  File "/var/lib/juju/agents/unit-postgresql-test-app-0/charm/./src/charm.py", line 538, in <module>
    main(ApplicationCharm)
  File "/var/lib/juju/agents/unit-postgresql-test-app-0/charm/venv/ops/main.py", line 553, in main
    manager.run()
  File "/var/lib/juju/agents/unit-postgresql-test-app-0/charm/venv/ops/main.py", line 529, in run
    self._emit()
  File "/var/lib/juju/agents/unit-postgresql-test-app-0/charm/venv/ops/main.py", line 518, in _emit
    _emit_charm_event(self.charm, self.dispatcher.event_name, self._juju_context)
  File "/var/lib/juju/agents/unit-postgresql-test-app-0/charm/venv/ops/main.py", line 139, in _emit_charm_event
    event_to_emit.emit(*args, **kwargs)
  File "/var/lib/juju/agents/unit-postgresql-test-app-0/charm/venv/ops/framework.py", line 347, in emit
    framework._emit(event)
  File "/var/lib/juju/agents/unit-postgresql-test-app-0/charm/venv/ops/framework.py", line 853, in _emit
    self._reemit(event_path)
  File "/var/lib/juju/agents/unit-postgresql-test-app-0/charm/venv/ops/framework.py", line 943, in _reemit
    custom_handler(event)
  File "/var/lib/juju/agents/unit-postgresql-test-app-0/charm/./src/charm.py", line 289, in _on_clear_continuous_writes_action
    if self._connection_string is None:
  File "/var/lib/juju/agents/unit-postgresql-test-app-0/charm/./src/charm.py", line 259, in _connection_string
    data = list(self.first_database.fetch_relation_data().values())[0]
AttributeError: 'ApplicationCharm' object has no attribute 'first_database'
unit-postgresql-test-app-0: 01:51:10 ERROR unit.postgresql-test-app/0.juju-log Uncaught exception while in charm code:
Traceback (most recent call last):
  File "/var/lib/juju/agents/unit-postgresql-test-app-0/charm/./src/charm.py", line 538, in <module>
    main(ApplicationCharm)
  File "/var/lib/juju/agents/unit-postgresql-test-app-0/charm/venv/ops/main.py", line 553, in main
    manager.run()
  File "/var/lib/juju/agents/unit-postgresql-test-app-0/charm/venv/ops/main.py", line 529, in run
    self._emit()
  File "/var/lib/juju/agents/unit-postgresql-test-app-0/charm/venv/ops/main.py", line 518, in _emit
    _emit_charm_event(self.charm, self.dispatcher.event_name, self._juju_context)
  File "/var/lib/juju/agents/unit-postgresql-test-app-0/charm/venv/ops/main.py", line 139, in _emit_charm_event
    event_to_emit.emit(*args, **kwargs)
  File "/var/lib/juju/agents/unit-postgresql-test-app-0/charm/venv/ops/framework.py", line 347, in emit
    framework._emit(event)
  File "/var/lib/juju/agents/unit-postgresql-test-app-0/charm/venv/ops/framework.py", line 853, in _emit
    self._reemit(event_path)
  File "/var/lib/juju/agents/unit-postgresql-test-app-0/charm/venv/ops/framework.py", line 943, in _reemit
    custom_handler(event)
  File "/var/lib/juju/agents/unit-postgresql-test-app-0/charm/./src/charm.py", line 289, in _on_clear_continuous_writes_action
    if self._connection_string is None:
  File "/var/lib/juju/agents/unit-postgresql-test-app-0/charm/./src/charm.py", line 259, in _connection_string
    data = list(self.first_database.fetch_relation_data().values())[0]
AttributeError: 'ApplicationCharm' object has no attribute 'first_database'
unit-postgresql-test-app-0: 01:51:14 ERROR unit.postgresql-test-app/0.juju-log Uncaught exception while in charm code:
Traceback (most recent call last):
  File "/var/lib/juju/agents/unit-postgresql-test-app-0/charm/./src/charm.py", line 538, in <module>
    main(ApplicationCharm)
  File "/var/lib/juju/agents/unit-postgresql-test-app-0/charm/venv/ops/main.py", line 553, in main
    manager.run()
  File "/var/lib/juju/agents/unit-postgresql-test-app-0/charm/venv/ops/main.py", line 529, in run
    self._emit()
  File "/var/lib/juju/agents/unit-postgresql-test-app-0/charm/venv/ops/main.py", line 518, in _emit
    _emit_charm_event(self.charm, self.dispatcher.event_name, self._juju_context)
  File "/var/lib/juju/agents/unit-postgresql-test-app-0/charm/venv/ops/main.py", line 139, in _emit_charm_event
    event_to_emit.emit(*args, **kwargs)
  File "/var/lib/juju/agents/unit-postgresql-test-app-0/charm/venv/ops/framework.py", line 347, in emit
    framework._emit(event)
  File "/var/lib/juju/agents/unit-postgresql-test-app-0/charm/venv/ops/framework.py", line 853, in _emit
    self._reemit(event_path)
  File "/var/lib/juju/agents/unit-postgresql-test-app-0/charm/venv/ops/framework.py", line 943, in _reemit
    custom_handler(event)
  File "/var/lib/juju/agents/unit-postgresql-test-app-0/charm/./src/charm.py", line 289, in _on_clear_continuous_writes_action
    if self._connection_string is None:
  File "/var/lib/juju/agents/unit-postgresql-test-app-0/charm/./src/charm.py", line 259, in _connection_string
    data = list(self.first_database.fetch_relation_data().values())[0]
AttributeError: 'ApplicationCharm' object has no attribute 'first_database'
unit-postgresql-test-app-0: 01:51:18 ERROR unit.postgresql-test-app/0.juju-log Uncaught exception while in charm code:
Traceback (most recent call last):
  File "/var/lib/juju/agents/unit-postgresql-test-app-0/charm/./src/charm.py", line 538, in <module>
    main(ApplicationCharm)
  File "/var/lib/juju/agents/unit-postgresql-test-app-0/charm/venv/ops/main.py", line 553, in main
    manager.run()
  File "/var/lib/juju/agents/unit-postgresql-test-app-0/charm/venv/ops/main.py", line 529, in run
    self._emit()
  File "/var/lib/juju/agents/unit-postgresql-test-app-0/charm/venv/ops/main.py", line 518, in _emit
    _emit_charm_event(self.charm, self.dispatcher.event_name, self._juju_context)
  File "/var/lib/juju/agents/unit-postgresql-test-app-0/charm/venv/ops/main.py", line 139, in _emit_charm_event
    event_to_emit.emit(*args, **kwargs)
  File "/var/lib/juju/agents/unit-postgresql-test-app-0/charm/venv/ops/framework.py", line 347, in emit
    framework._emit(event)
  File "/var/lib/juju/agents/unit-postgresql-test-app-0/charm/venv/ops/framework.py", line 853, in _emit
    self._reemit(event_path)
  File "/var/lib/juju/agents/unit-postgresql-test-app-0/charm/venv/ops/framework.py", line 943, in _reemit
    custom_handler(event)
  File "/var/lib/juju/agents/unit-postgresql-test-app-0/charm/./src/charm.py", line 289, in _on_clear_continuous_writes_action
    if self._connection_string is None:
  File "/var/lib/juju/agents/unit-postgresql-test-app-0/charm/./src/charm.py", line 259, in _connection_string
    data = list(self.first_database.fetch_relation_data().values())[0]
AttributeError: 'ApplicationCharm' object has no attribute 'first_database'
unit-postgresql-test-app-0: 01:51:22 ERROR unit.postgresql-test-app/0.juju-log Uncaught exception while in charm code:
Traceback (most recent call last):
  File "/var/lib/juju/agents/unit-postgresql-test-app-0/charm/./src/charm.py", line 538, in <module>
    main(ApplicationCharm)
  File "/var/lib/juju/agents/unit-postgresql-test-app-0/charm/venv/ops/main.py", line 553, in main
    manager.run()
  File "/var/lib/juju/agents/unit-postgresql-test-app-0/charm/venv/ops/main.py", line 529, in run
    self._emit()
  File "/var/lib/juju/agents/unit-postgresql-test-app-0/charm/venv/ops/main.py", line 518, in _emit
    _emit_charm_event(self.charm, self.dispatcher.event_name, self._juju_context)
  File "/var/lib/juju/agents/unit-postgresql-test-app-0/charm/venv/ops/main.py", line 139, in _emit_charm_event
    event_to_emit.emit(*args, **kwargs)
  File "/var/lib/juju/agents/unit-postgresql-test-app-0/charm/venv/ops/framework.py", line 347, in emit
    framework._emit(event)
  File "/var/lib/juju/agents/unit-postgresql-test-app-0/charm/venv/ops/framework.py", line 853, in _emit
    self._reemit(event_path)
  File "/var/lib/juju/agents/unit-postgresql-test-app-0/charm/venv/ops/framework.py", line 943, in _reemit
    custom_handler(event)
  File "/var/lib/juju/agents/unit-postgresql-test-app-0/charm/./src/charm.py", line 289, in _on_clear_continuous_writes_action
    if self._connection_string is None:
  File "/var/lib/juju/agents/unit-postgresql-test-app-0/charm/./src/charm.py", line 259, in _connection_string
    data = list(self.first_database.fetch_relation_data().values())[0]
AttributeError: 'ApplicationCharm' object has no attribute 'first_database'
unit-postgresql-test-app-0: 01:51:26 ERROR unit.postgresql-test-app/0.juju-log Uncaught exception while in charm code:
Traceback (most recent call last):
  File "/var/lib/juju/agents/unit-postgresql-test-app-0/charm/./src/charm.py", line 538, in <module>
    main(ApplicationCharm)
  File "/var/lib/juju/agents/unit-postgresql-test-app-0/charm/venv/ops/main.py", line 553, in main
    manager.run()
  File "/var/lib/juju/agents/unit-postgresql-test-app-0/charm/venv/ops/main.py", line 529, in run
    self._emit()
  File "/var/lib/juju/agents/unit-postgresql-test-app-0/charm/venv/ops/main.py", line 518, in _emit
    _emit_charm_event(self.charm, self.dispatcher.event_name, self._juju_context)
  File "/var/lib/juju/agents/unit-postgresql-test-app-0/charm/venv/ops/main.py", line 139, in _emit_charm_event
    event_to_emit.emit(*args, **kwargs)
  File "/var/lib/juju/agents/unit-postgresql-test-app-0/charm/venv/ops/framework.py", line 347, in emit
    framework._emit(event)
  File "/var/lib/juju/agents/unit-postgresql-test-app-0/charm/venv/ops/framework.py", line 853, in _emit
    self._reemit(event_path)
  File "/var/lib/juju/agents/unit-postgresql-test-app-0/charm/venv/ops/framework.py", line 943, in _reemit
    custom_handler(event)
  File "/var/lib/juju/agents/unit-postgresql-test-app-0/charm/./src/charm.py", line 289, in _on_clear_continuous_writes_action
    if self._connection_string is None:
  File "/var/lib/juju/agents/unit-postgresql-test-app-0/charm/./src/charm.py", line 259, in _connection_string
    data = list(self.first_database.fetch_relation_data().values())[0]
AttributeError: 'ApplicationCharm' object has no attribute 'first_database'
unit-postgresql-test-app-0: 01:51:30 ERROR unit.postgresql-test-app/0.juju-log Uncaught exception while in charm code:
Traceback (most recent call last):
  File "/var/lib/juju/agents/unit-postgresql-test-app-0/charm/./src/charm.py", line 538, in <module>
    main(ApplicationCharm)
  File "/var/lib/juju/agents/unit-postgresql-test-app-0/charm/venv/ops/main.py", line 553, in main
    manager.run()
  File "/var/lib/juju/agents/unit-postgresql-test-app-0/charm/venv/ops/main.py", line 529, in run
    self._emit()
  File "/var/lib/juju/agents/unit-postgresql-test-app-0/charm/venv/ops/main.py", line 518, in _emit
    _emit_charm_event(self.charm, self.dispatcher.event_name, self._juju_context)
  File "/var/lib/juju/agents/unit-postgresql-test-app-0/charm/venv/ops/main.py", line 139, in _emit_charm_event
    event_to_emit.emit(*args, **kwargs)
  File "/var/lib/juju/agents/unit-postgresql-test-app-0/charm/venv/ops/framework.py", line 347, in emit
    framework._emit(event)
  File "/var/lib/juju/agents/unit-postgresql-test-app-0/charm/venv/ops/framework.py", line 853, in _emit
    self._reemit(event_path)
  File "/var/lib/juju/agents/unit-postgresql-test-app-0/charm/venv/ops/framework.py", line 943, in _reemit
    custom_handler(event)
  File "/var/lib/juju/agents/unit-postgresql-test-app-0/charm/./src/charm.py", line 289, in _on_clear_continuous_writes_action
    if self._connection_string is None:
  File "/var/lib/juju/agents/unit-postgresql-test-app-0/charm/./src/charm.py", line 259, in _connection_string
    data = list(self.first_database.fetch_relation_data().values())[0]
AttributeError: 'ApplicationCharm' object has no attribute 'first_database'
unit-postgresql-test-app-0: 01:51:34 ERROR unit.postgresql-test-app/0.juju-log Uncaught exception while in charm code:
Traceback (most recent call last):
  File "/var/lib/juju/agents/unit-postgresql-test-app-0/charm/./src/charm.py", line 538, in <module>
    main(ApplicationCharm)
  File "/var/lib/juju/agents/unit-postgresql-test-app-0/charm/venv/ops/main.py", line 553, in main
    manager.run()
  File "/var/lib/juju/agents/unit-postgresql-test-app-0/charm/venv/ops/main.py", line 529, in run
    self._emit()
  File "/var/lib/juju/agents/unit-postgresql-test-app-0/charm/venv/ops/main.py", line 518, in _emit
    _emit_charm_event(self.charm, self.dispatcher.event_name, self._juju_context)
  File "/var/lib/juju/agents/unit-postgresql-test-app-0/charm/venv/ops/main.py", line 139, in _emit_charm_event
    event_to_emit.emit(*args, **kwargs)
  File "/var/lib/juju/agents/unit-postgresql-test-app-0/charm/venv/ops/framework.py", line 347, in emit
    framework._emit(event)
  File "/var/lib/juju/agents/unit-postgresql-test-app-0/charm/venv/ops/framework.py", line 853, in _emit
    self._reemit(event_path)
  File "/var/lib/juju/agents/unit-postgresql-test-app-0/charm/venv/ops/framework.py", line 943, in _reemit
    custom_handler(event)
  File "/var/lib/juju/agents/unit-postgresql-test-app-0/charm/./src/charm.py", line 289, in _on_clear_continuous_writes_action
    if self._connection_string is None:
  File "/var/lib/juju/agents/unit-postgresql-test-app-0/charm/./src/charm.py", line 259, in _connection_string
    data = list(self.first_database.fetch_relation_data().values())[0]
AttributeError: 'ApplicationCharm' object has no attribute 'first_database'
unit-postgresql-test-app-0: 01:51:38 ERROR unit.postgresql-test-app/0.juju-log Uncaught exception while in charm code:
Traceback (most recent call last):
  File "/var/lib/juju/agents/unit-postgresql-test-app-0/charm/./src/charm.py", line 538, in <module>
    main(ApplicationCharm)
  File "/var/lib/juju/agents/unit-postgresql-test-app-0/charm/venv/ops/main.py", line 553, in main
    manager.run()
  File "/var/lib/juju/agents/unit-postgresql-test-app-0/charm/venv/ops/main.py", line 529, in run
    self._emit()
  File "/var/lib/juju/agents/unit-postgresql-test-app-0/charm/venv/ops/main.py", line 518, in _emit
    _emit_charm_event(self.charm, self.dispatcher.event_name, self._juju_context)
  File "/var/lib/juju/agents/unit-postgresql-test-app-0/charm/venv/ops/main.py", line 139, in _emit_charm_event
    event_to_emit.emit(*args, **kwargs)
  File "/var/lib/juju/agents/unit-postgresql-test-app-0/charm/venv/ops/framework.py", line 347, in emit
    framework._emit(event)
  File "/var/lib/juju/agents/unit-postgresql-test-app-0/charm/venv/ops/framework.py", line 853, in _emit
    self._reemit(event_path)
  File "/var/lib/juju/agents/unit-postgresql-test-app-0/charm/venv/ops/framework.py", line 943, in _reemit
    custom_handler(event)
  File "/var/lib/juju/agents/unit-postgresql-test-app-0/charm/./src/charm.py", line 289, in _on_clear_continuous_writes_action
    if self._connection_string is None:
  File "/var/lib/juju/agents/unit-postgresql-test-app-0/charm/./src/charm.py", line 259, in _connection_string
    data = list(self.first_database.fetch_relation_data().values())[0]
AttributeError: 'ApplicationCharm' object has no attribute 'first_database'
unit-postgresql-test-app-0: 01:51:42 ERROR unit.postgresql-test-app/0.juju-log Uncaught exception while in charm code:
Traceback (most recent call last):
  File "/var/lib/juju/agents/unit-postgresql-test-app-0/charm/./src/charm.py", line 538, in <module>
    main(ApplicationCharm)
  File "/var/lib/juju/agents/unit-postgresql-test-app-0/charm/venv/ops/main.py", line 553, in main
    manager.run()
  File "/var/lib/juju/agents/unit-postgresql-test-app-0/charm/venv/ops/main.py", line 529, in run
    self._emit()
  File "/var/lib/juju/agents/unit-postgresql-test-app-0/charm/venv/ops/main.py", line 518, in _emit
    _emit_charm_event(self.charm, self.dispatcher.event_name, self._juju_context)
  File "/var/lib/juju/agents/unit-postgresql-test-app-0/charm/venv/ops/main.py", line 139, in _emit_charm_event
    event_to_emit.emit(*args, **kwargs)
  File "/var/lib/juju/agents/unit-postgresql-test-app-0/charm/venv/ops/framework.py", line 347, in emit
    framework._emit(event)
  File "/var/lib/juju/agents/unit-postgresql-test-app-0/charm/venv/ops/framework.py", line 853, in _emit
    self._reemit(event_path)
  File "/var/lib/juju/agents/unit-postgresql-test-app-0/charm/venv/ops/framework.py", line 943, in _reemit
    custom_handler(event)
  File "/var/lib/juju/agents/unit-postgresql-test-app-0/charm/./src/charm.py", line 289, in _on_clear_continuous_writes_action
    if self._connection_string is None:
  File "/var/lib/juju/agents/unit-postgresql-test-app-0/charm/./src/charm.py", line 259, in _connection_string
    data = list(self.first_database.fetch_relation_data().values())[0]
AttributeError: 'ApplicationCharm' object has no attribute 'first_database'
unit-postgresql-test-app-0: 01:51:46 ERROR unit.postgresql-test-app/0.juju-log Uncaught exception while in charm code:
Traceback (most recent call last):
  File "/var/lib/juju/agents/unit-postgresql-test-app-0/charm/./src/charm.py", line 538, in <module>
    main(ApplicationCharm)
  File "/var/lib/juju/agents/unit-postgresql-test-app-0/charm/venv/ops/main.py", line 553, in main
    manager.run()
  File "/var/lib/juju/agents/unit-postgresql-test-app-0/charm/venv/ops/main.py", line 529, in run
    self._emit()
  File "/var/lib/juju/agents/unit-postgresql-test-app-0/charm/venv/ops/main.py", line 518, in _emit
    _emit_charm_event(self.charm, self.dispatcher.event_name, self._juju_context)
  File "/var/lib/juju/agents/unit-postgresql-test-app-0/charm/venv/ops/main.py", line 139, in _emit_charm_event
    event_to_emit.emit(*args, **kwargs)
  File "/var/lib/juju/agents/unit-postgresql-test-app-0/charm/venv/ops/framework.py", line 347, in emit
    framework._emit(event)
  File "/var/lib/juju/agents/unit-postgresql-test-app-0/charm/venv/ops/framework.py", line 853, in _emit
    self._reemit(event_path)
  File "/var/lib/juju/agents/unit-postgresql-test-app-0/charm/venv/ops/framework.py", line 943, in _reemit
    custom_handler(event)
  File "/var/lib/juju/agents/unit-postgresql-test-app-0/charm/./src/charm.py", line 289, in _on_clear_continuous_writes_action
    if self._connection_string is None:
  File "/var/lib/juju/agents/unit-postgresql-test-app-0/charm/./src/charm.py", line 259, in _connection_string
    data = list(self.first_database.fetch_relation_data().values())[0]
AttributeError: 'ApplicationCharm' object has no attribute 'first_database'
unit-postgresql-test-app-0: 01:51:50 ERROR unit.postgresql-test-app/0.juju-log Uncaught exception while in charm code:
Traceback (most recent call last):
  File "/var/lib/juju/agents/unit-postgresql-test-app-0/charm/./src/charm.py", line 538, in <module>
    main(ApplicationCharm)
  File "/var/lib/juju/agents/unit-postgresql-test-app-0/charm/venv/ops/main.py", line 553, in main
    manager.run()
  File "/var/lib/juju/agents/unit-postgresql-test-app-0/charm/venv/ops/main.py", line 529, in run
    self._emit()
  File "/var/lib/juju/agents/unit-postgresql-test-app-0/charm/venv/ops/main.py", line 518, in _emit
    _emit_charm_event(self.charm, self.dispatcher.event_name, self._juju_context)
  File "/var/lib/juju/agents/unit-postgresql-test-app-0/charm/venv/ops/main.py", line 139, in _emit_charm_event
    event_to_emit.emit(*args, **kwargs)
  File "/var/lib/juju/agents/unit-postgresql-test-app-0/charm/venv/ops/framework.py", line 347, in emit
    framework._emit(event)
  File "/var/lib/juju/agents/unit-postgresql-test-app-0/charm/venv/ops/framework.py", line 853, in _emit
    self._reemit(event_path)
  File "/var/lib/juju/agents/unit-postgresql-test-app-0/charm/venv/ops/framework.py", line 943, in _reemit
    custom_handler(event)
  File "/var/lib/juju/agents/unit-postgresql-test-app-0/charm/./src/charm.py", line 289, in _on_clear_continuous_writes_action
    if self._connection_string is None:
  File "/var/lib/juju/agents/unit-postgresql-test-app-0/charm/./src/charm.py", line 259, in _connection_string
    data = list(self.first_database.fetch_relation_data().values())[0]
AttributeError: 'ApplicationCharm' object has no attribute 'first_database'
unit-postgresql-test-app-0: 01:51:54 ERROR unit.postgresql-test-app/0.juju-log Uncaught exception while in charm code:
Traceback (most recent call last):
  File "/var/lib/juju/agents/unit-postgresql-test-app-0/charm/./src/charm.py", line 538, in <module>
    main(ApplicationCharm)
  File "/var/lib/juju/agents/unit-postgresql-test-app-0/charm/venv/ops/main.py", line 553, in main
    manager.run()
  File "/var/lib/juju/agents/unit-postgresql-test-app-0/charm/venv/ops/main.py", line 529, in run
    self._emit()
  File "/var/lib/juju/agents/unit-postgresql-test-app-0/charm/venv/ops/main.py", line 518, in _emit
    _emit_charm_event(self.charm, self.dispatcher.event_name, self._juju_context)
  File "/var/lib/juju/agents/unit-postgresql-test-app-0/charm/venv/ops/main.py", line 139, in _emit_charm_event
    event_to_emit.emit(*args, **kwargs)
  File "/var/lib/juju/agents/unit-postgresql-test-app-0/charm/venv/ops/framework.py", line 347, in emit
    framework._emit(event)
  File "/var/lib/juju/agents/unit-postgresql-test-app-0/charm/venv/ops/framework.py", line 853, in _emit
    self._reemit(event_path)
  File "/var/lib/juju/agents/unit-postgresql-test-app-0/charm/venv/ops/framework.py", line 943, in _reemit
    custom_handler(event)
  File "/var/lib/juju/agents/unit-postgresql-test-app-0/charm/./src/charm.py", line 289, in _on_clear_continuous_writes_action
    if self._connection_string is None:
  File "/var/lib/juju/agents/unit-postgresql-test-app-0/charm/./src/charm.py", line 259, in _connection_string
    data = list(self.first_database.fetch_relation_data().values())[0]
AttributeError: 'ApplicationCharm' object has no attribute 'first_database'
unit-postgresql-test-app-0: 01:51:58 ERROR unit.postgresql-test-app/0.juju-log Uncaught exception while in charm code:
Traceback (most recent call last):
  File "/var/lib/juju/agents/unit-postgresql-test-app-0/charm/./src/charm.py", line 538, in <module>
    main(ApplicationCharm)
  File "/var/lib/juju/agents/unit-postgresql-test-app-0/charm/venv/ops/main.py", line 553, in main
    manager.run()
  File "/var/lib/juju/agents/unit-postgresql-test-app-0/charm/venv/ops/main.py", line 529, in run
    self._emit()
  File "/var/lib/juju/agents/unit-postgresql-test-app-0/charm/venv/ops/main.py", line 518, in _emit
    _emit_charm_event(self.charm, self.dispatcher.event_name, self._juju_context)
  File "/var/lib/juju/agents/unit-postgresql-test-app-0/charm/venv/ops/main.py", line 139, in _emit_charm_event
    event_to_emit.emit(*args, **kwargs)
  File "/var/lib/juju/agents/unit-postgresql-test-app-0/charm/venv/ops/framework.py", line 347, in emit
    framework._emit(event)
  File "/var/lib/juju/agents/unit-postgresql-test-app-0/charm/venv/ops/framework.py", line 853, in _emit
    self._reemit(event_path)
  File "/var/lib/juju/agents/unit-postgresql-test-app-0/charm/venv/ops/framework.py", line 943, in _reemit
    custom_handler(event)
  File "/var/lib/juju/agents/unit-postgresql-test-app-0/charm/./src/charm.py", line 289, in _on_clear_continuous_writes_action
    if self._connection_string is None:
  File "/var/lib/juju/agents/unit-postgresql-test-app-0/charm/./src/charm.py", line 259, in _connection_string
    data = list(self.first_database.fetch_relation_data().values())[0]
AttributeError: 'ApplicationCharm' object has no attribute 'first_database'
unit-postgresql-test-app-0: 01:52:02 ERROR unit.postgresql-test-app/0.juju-log Uncaught exception while in charm code:
Traceback (most recent call last):
  File "/var/lib/juju/agents/unit-postgresql-test-app-0/charm/./src/charm.py", line 538, in <module>
    main(ApplicationCharm)
  File "/var/lib/juju/agents/unit-postgresql-test-app-0/charm/venv/ops/main.py", line 553, in main
    manager.run()
  File "/var/lib/juju/agents/unit-postgresql-test-app-0/charm/venv/ops/main.py", line 529, in run
    self._emit()
  File "/var/lib/juju/agents/unit-postgresql-test-app-0/charm/venv/ops/main.py", line 518, in _emit
    _emit_charm_event(self.charm, self.dispatcher.event_name, self._juju_context)
  File "/var/lib/juju/agents/unit-postgresql-test-app-0/charm/venv/ops/main.py", line 139, in _emit_charm_event
    event_to_emit.emit(*args, **kwargs)
  File "/var/lib/juju/agents/unit-postgresql-test-app-0/charm/venv/ops/framework.py", line 347, in emit
    framework._emit(event)
  File "/var/lib/juju/agents/unit-postgresql-test-app-0/charm/venv/ops/framework.py", line 853, in _emit
    self._reemit(event_path)
  File "/var/lib/juju/agents/unit-postgresql-test-app-0/charm/venv/ops/framework.py", line 943, in _reemit
    custom_handler(event)
  File "/var/lib/juju/agents/unit-postgresql-test-app-0/charm/./src/charm.py", line 289, in _on_clear_continuous_writes_action
    if self._connection_string is None:
  File "/var/lib/juju/agents/unit-postgresql-test-app-0/charm/./src/charm.py", line 259, in _connection_string
    data = list(self.first_database.fetch_relation_data().values())[0]
AttributeError: 'ApplicationCharm' object has no attribute 'first_database'
unit-postgresql-test-app-0: 01:52:06 ERROR unit.postgresql-test-app/0.juju-log Uncaught exception while in charm code:
Traceback (most recent call last):
  File "/var/lib/juju/agents/unit-postgresql-test-app-0/charm/./src/charm.py", line 538, in <module>
    main(ApplicationCharm)
  File "/var/lib/juju/agents/unit-postgresql-test-app-0/charm/venv/ops/main.py", line 553, in main
    manager.run()
  File "/var/lib/juju/agents/unit-postgresql-test-app-0/charm/venv/ops/main.py", line 529, in run
    self._emit()
  File "/var/lib/juju/agents/unit-postgresql-test-app-0/charm/venv/ops/main.py", line 518, in _emit
    _emit_charm_event(self.charm, self.dispatcher.event_name, self._juju_context)
  File "/var/lib/juju/agents/unit-postgresql-test-app-0/charm/venv/ops/main.py", line 139, in _emit_charm_event
    event_to_emit.emit(*args, **kwargs)
  File "/var/lib/juju/agents/unit-postgresql-test-app-0/charm/venv/ops/framework.py", line 347, in emit
    framework._emit(event)
  File "/var/lib/juju/agents/unit-postgresql-test-app-0/charm/venv/ops/framework.py", line 853, in _emit
    self._reemit(event_path)
  File "/var/lib/juju/agents/unit-postgresql-test-app-0/charm/venv/ops/framework.py", line 943, in _reemit
    custom_handler(event)
  File "/var/lib/juju/agents/unit-postgresql-test-app-0/charm/./src/charm.py", line 289, in _on_clear_continuous_writes_action
    if self._connection_string is None:
  File "/var/lib/juju/agents/unit-postgresql-test-app-0/charm/./src/charm.py", line 259, in _connection_string
    data = list(self.first_database.fetch_relation_data().values())[0]
AttributeError: 'ApplicationCharm' object has no attribute 'first_database'
unit-postgresql-test-app-0: 01:52:10 ERROR unit.postgresql-test-app/0.juju-log Uncaught exception while in charm code:
Traceback (most recent call last):
  File "/var/lib/juju/agents/unit-postgresql-test-app-0/charm/./src/charm.py", line 538, in <module>
    main(ApplicationCharm)
  File "/var/lib/juju/agents/unit-postgresql-test-app-0/charm/venv/ops/main.py", line 553, in main
    manager.run()
  File "/var/lib/juju/agents/unit-postgresql-test-app-0/charm/venv/ops/main.py", line 529, in run
    self._emit()
  File "/var/lib/juju/agents/unit-postgresql-test-app-0/charm/venv/ops/main.py", line 518, in _emit
    _emit_charm_event(self.charm, self.dispatcher.event_name, self._juju_context)
  File "/var/lib/juju/agents/unit-postgresql-test-app-0/charm/venv/ops/main.py", line 139, in _emit_charm_event
    event_to_emit.emit(*args, **kwargs)
  File "/var/lib/juju/agents/unit-postgresql-test-app-0/charm/venv/ops/framework.py", line 347, in emit
    framework._emit(event)
  File "/var/lib/juju/agents/unit-postgresql-test-app-0/charm/venv/ops/framework.py", line 853, in _emit
    self._reemit(event_path)
  File "/var/lib/juju/agents/unit-postgresql-test-app-0/charm/venv/ops/framework.py", line 943, in _reemit
    custom_handler(event)
  File "/var/lib/juju/agents/unit-postgresql-test-app-0/charm/./src/charm.py", line 289, in _on_clear_continuous_writes_action
    if self._connection_string is None:
  File "/var/lib/juju/agents/unit-postgresql-test-app-0/charm/./src/charm.py", line 259, in _connection_string
    data = list(self.first_database.fetch_relation_data().values())[0]
AttributeError: 'ApplicationCharm' object has no attribute 'first_database'
unit-postgresql-test-app-0: 01:52:14 ERROR unit.postgresql-test-app/0.juju-log Uncaught exception while in charm code:
Traceback (most recent call last):
  File "/var/lib/juju/agents/unit-postgresql-test-app-0/charm/./src/charm.py", line 538, in <module>
    main(ApplicationCharm)
  File "/var/lib/juju/agents/unit-postgresql-test-app-0/charm/venv/ops/main.py", line 553, in main
    manager.run()
  File "/var/lib/juju/agents/unit-postgresql-test-app-0/charm/venv/ops/main.py", line 529, in run
    self._emit()
  File "/var/lib/juju/agents/unit-postgresql-test-app-0/charm/venv/ops/main.py", line 518, in _emit
    _emit_charm_event(self.charm, self.dispatcher.event_name, self._juju_context)
  File "/var/lib/juju/agents/unit-postgresql-test-app-0/charm/venv/ops/main.py", line 139, in _emit_charm_event
    event_to_emit.emit(*args, **kwargs)
  File "/var/lib/juju/agents/unit-postgresql-test-app-0/charm/venv/ops/framework.py", line 347, in emit
    framework._emit(event)
  File "/var/lib/juju/agents/unit-postgresql-test-app-0/charm/venv/ops/framework.py", line 853, in _emit
    self._reemit(event_path)
  File "/var/lib/juju/agents/unit-postgresql-test-app-0/charm/venv/ops/framework.py", line 943, in _reemit
    custom_handler(event)
  File "/var/lib/juju/agents/unit-postgresql-test-app-0/charm/./src/charm.py", line 289, in _on_clear_continuous_writes_action
    if self._connection_string is None:
  File "/var/lib/juju/agents/unit-postgresql-test-app-0/charm/./src/charm.py", line 259, in _connection_string
    data = list(self.first_database.fetch_relation_data().values())[0]
AttributeError: 'ApplicationCharm' object has no attribute 'first_database'
unit-postgresql-test-app-0: 01:52:18 ERROR unit.postgresql-test-app/0.juju-log Uncaught exception while in charm code:
Traceback (most recent call last):
  File "/var/lib/juju/agents/unit-postgresql-test-app-0/charm/./src/charm.py", line 538, in <module>
    main(ApplicationCharm)
  File "/var/lib/juju/agents/unit-postgresql-test-app-0/charm/venv/ops/main.py", line 553, in main
    manager.run()
  File "/var/lib/juju/agents/unit-postgresql-test-app-0/charm/venv/ops/main.py", line 529, in run
    self._emit()
  File "/var/lib/juju/agents/unit-postgresql-test-app-0/charm/venv/ops/main.py", line 518, in _emit
    _emit_charm_event(self.charm, self.dispatcher.event_name, self._juju_context)
  File "/var/lib/juju/agents/unit-postgresql-test-app-0/charm/venv/ops/main.py", line 139, in _emit_charm_event
    event_to_emit.emit(*args, **kwargs)
  File "/var/lib/juju/agents/unit-postgresql-test-app-0/charm/venv/ops/framework.py", line 347, in emit
    framework._emit(event)
  File "/var/lib/juju/agents/unit-postgresql-test-app-0/charm/venv/ops/framework.py", line 853, in _emit
    self._reemit(event_path)
  File "/var/lib/juju/agents/unit-postgresql-test-app-0/charm/venv/ops/framework.py", line 943, in _reemit
    custom_handler(event)
  File "/var/lib/juju/agents/unit-postgresql-test-app-0/charm/./src/charm.py", line 289, in _on_clear_continuous_writes_action
    if self._connection_string is None:
  File "/var/lib/juju/agents/unit-postgresql-test-app-0/charm/./src/charm.py", line 259, in _connection_string
    data = list(self.first_database.fetch_relation_data().values())[0]
AttributeError: 'ApplicationCharm' object has no attribute 'first_database'
unit-postgresql-test-app-0: 01:52:23 ERROR unit.postgresql-test-app/0.juju-log Uncaught exception while in charm code:
Traceback (most recent call last):
  File "/var/lib/juju/agents/unit-postgresql-test-app-0/charm/./src/charm.py", line 538, in <module>
    main(ApplicationCharm)
  File "/var/lib/juju/agents/unit-postgresql-test-app-0/charm/venv/ops/main.py", line 553, in main
    manager.run()
  File "/var/lib/juju/agents/unit-postgresql-test-app-0/charm/venv/ops/main.py", line 529, in run
    self._emit()
  File "/var/lib/juju/agents/unit-postgresql-test-app-0/charm/venv/ops/main.py", line 518, in _emit
    _emit_charm_event(self.charm, self.dispatcher.event_name, self._juju_context)
  File "/var/lib/juju/agents/unit-postgresql-test-app-0/charm/venv/ops/main.py", line 139, in _emit_charm_event
    event_to_emit.emit(*args, **kwargs)
  File "/var/lib/juju/agents/unit-postgresql-test-app-0/charm/venv/ops/framework.py", line 347, in emit
    framework._emit(event)
  File "/var/lib/juju/agents/unit-postgresql-test-app-0/charm/venv/ops/framework.py", line 853, in _emit
    self._reemit(event_path)
  File "/var/lib/juju/agents/unit-postgresql-test-app-0/charm/venv/ops/framework.py", line 943, in _reemit
    custom_handler(event)
  File "/var/lib/juju/agents/unit-postgresql-test-app-0/charm/./src/charm.py", line 289, in _on_clear_continuous_writes_action
    if self._connection_string is None:
  File "/var/lib/juju/agents/unit-postgresql-test-app-0/charm/./src/charm.py", line 259, in _connection_string
    data = list(self.first_database.fetch_relation_data().values())[0]
AttributeError: 'ApplicationCharm' object has no attribute 'first_database'
unit-postgresql-test-app-0: 01:52:27 ERROR unit.postgresql-test-app/0.juju-log Uncaught exception while in charm code:
Traceback (most recent call last):
  File "/var/lib/juju/agents/unit-postgresql-test-app-0/charm/./src/charm.py", line 538, in <module>
    main(ApplicationCharm)
  File "/var/lib/juju/agents/unit-postgresql-test-app-0/charm/venv/ops/main.py", line 553, in main
    manager.run()
  File "/var/lib/juju/agents/unit-postgresql-test-app-0/charm/venv/ops/main.py", line 529, in run
    self._emit()
  File "/var/lib/juju/agents/unit-postgresql-test-app-0/charm/venv/ops/main.py", line 518, in _emit
    _emit_charm_event(self.charm, self.dispatcher.event_name, self._juju_context)
  File "/var/lib/juju/agents/unit-postgresql-test-app-0/charm/venv/ops/main.py", line 139, in _emit_charm_event
    event_to_emit.emit(*args, **kwargs)
  File "/var/lib/juju/agents/unit-postgresql-test-app-0/charm/venv/ops/framework.py", line 347, in emit
    framework._emit(event)
  File "/var/lib/juju/agents/unit-postgresql-test-app-0/charm/venv/ops/framework.py", line 853, in _emit
    self._reemit(event_path)
  File "/var/lib/juju/agents/unit-postgresql-test-app-0/charm/venv/ops/framework.py", line 943, in _reemit
    custom_handler(event)
  File "/var/lib/juju/agents/unit-postgresql-test-app-0/charm/./src/charm.py", line 289, in _on_clear_continuous_writes_action
    if self._connection_string is None:
  File "/var/lib/juju/agents/unit-postgresql-test-app-0/charm/./src/charm.py", line 259, in _connection_string
    data = list(self.first_database.fetch_relation_data().values())[0]
AttributeError: 'ApplicationCharm' object has no attribute 'first_database'
unit-postgresql-test-app-0: 01:52:31 ERROR unit.postgresql-test-app/0.juju-log Uncaught exception while in charm code:
Traceback (most recent call last):
  File "/var/lib/juju/agents/unit-postgresql-test-app-0/charm/./src/charm.py", line 538, in <module>
    main(ApplicationCharm)
  File "/var/lib/juju/agents/unit-postgresql-test-app-0/charm/venv/ops/main.py", line 553, in main
    manager.run()
  File "/var/lib/juju/agents/unit-postgresql-test-app-0/charm/venv/ops/main.py", line 529, in run
    self._emit()
  File "/var/lib/juju/agents/unit-postgresql-test-app-0/charm/venv/ops/main.py", line 518, in _emit
    _emit_charm_event(self.charm, self.dispatcher.event_name, self._juju_context)
  File "/var/lib/juju/agents/unit-postgresql-test-app-0/charm/venv/ops/main.py", line 139, in _emit_charm_event
    event_to_emit.emit(*args, **kwargs)
  File "/var/lib/juju/agents/unit-postgresql-test-app-0/charm/venv/ops/framework.py", line 347, in emit
    framework._emit(event)
  File "/var/lib/juju/agents/unit-postgresql-test-app-0/charm/venv/ops/framework.py", line 853, in _emit
    self._reemit(event_path)
  File "/var/lib/juju/agents/unit-postgresql-test-app-0/charm/venv/ops/framework.py", line 943, in _reemit
    custom_handler(event)
  File "/var/lib/juju/agents/unit-postgresql-test-app-0/charm/./src/charm.py", line 289, in _on_clear_continuous_writes_action
    if self._connection_string is None:
  File "/var/lib/juju/agents/unit-postgresql-test-app-0/charm/./src/charm.py", line 259, in _connection_string
    data = list(self.first_database.fetch_relation_data().values())[0]
AttributeError: 'ApplicationCharm' object has no attribute 'first_database'
unit-postgresql-test-app-0: 01:52:35 ERROR unit.postgresql-test-app/0.juju-log Uncaught exception while in charm code:
Traceback (most recent call last):
  File "/var/lib/juju/agents/unit-postgresql-test-app-0/charm/./src/charm.py", line 538, in <module>
    main(ApplicationCharm)
  File "/var/lib/juju/agents/unit-postgresql-test-app-0/charm/venv/ops/main.py", line 553, in main
    manager.run()
  File "/var/lib/juju/agents/unit-postgresql-test-app-0/charm/venv/ops/main.py", line 529, in run
    self._emit()
  File "/var/lib/juju/agents/unit-postgresql-test-app-0/charm/venv/ops/main.py", line 518, in _emit
    _emit_charm_event(self.charm, self.dispatcher.event_name, self._juju_context)
  File "/var/lib/juju/agents/unit-postgresql-test-app-0/charm/venv/ops/main.py", line 139, in _emit_charm_event
    event_to_emit.emit(*args, **kwargs)
  File "/var/lib/juju/agents/unit-postgresql-test-app-0/charm/venv/ops/framework.py", line 347, in emit
    framework._emit(event)
  File "/var/lib/juju/agents/unit-postgresql-test-app-0/charm/venv/ops/framework.py", line 853, in _emit
    self._reemit(event_path)
  File "/var/lib/juju/agents/unit-postgresql-test-app-0/charm/venv/ops/framework.py", line 943, in _reemit
    custom_handler(event)
  File "/var/lib/juju/agents/unit-postgresql-test-app-0/charm/./src/charm.py", line 289, in _on_clear_continuous_writes_action
    if self._connection_string is None:
  File "/var/lib/juju/agents/unit-postgresql-test-app-0/charm/./src/charm.py", line 259, in _connection_string
    data = list(self.first_database.fetch_relation_data().values())[0]
AttributeError: 'ApplicationCharm' object has no attribute 'first_database'
unit-postgresql-test-app-0: 01:52:39 ERROR unit.postgresql-test-app/0.juju-log Uncaught exception while in charm code:
Traceback (most recent call last):
  File "/var/lib/juju/agents/unit-postgresql-test-app-0/charm/./src/charm.py", line 538, in <module>
    main(ApplicationCharm)
  File "/var/lib/juju/agents/unit-postgresql-test-app-0/charm/venv/ops/main.py", line 553, in main
    manager.run()
  File "/var/lib/juju/agents/unit-postgresql-test-app-0/charm/venv/ops/main.py", line 529, in run
    self._emit()
  File "/var/lib/juju/agents/unit-postgresql-test-app-0/charm/venv/ops/main.py", line 518, in _emit
    _emit_charm_event(self.charm, self.dispatcher.event_name, self._juju_context)
  File "/var/lib/juju/agents/unit-postgresql-test-app-0/charm/venv/ops/main.py", line 139, in _emit_charm_event
    event_to_emit.emit(*args, **kwargs)
  File "/var/lib/juju/agents/unit-postgresql-test-app-0/charm/venv/ops/framework.py", line 347, in emit
    framework._emit(event)
  File "/var/lib/juju/agents/unit-postgresql-test-app-0/charm/venv/ops/framework.py", line 853, in _emit
    self._reemit(event_path)
  File "/var/lib/juju/agents/unit-postgresql-test-app-0/charm/venv/ops/framework.py", line 943, in _reemit
    custom_handler(event)
  File "/var/lib/juju/agents/unit-postgresql-test-app-0/charm/./src/charm.py", line 289, in _on_clear_continuous_writes_action
    if self._connection_string is None:
  File "/var/lib/juju/agents/unit-postgresql-test-app-0/charm/./src/charm.py", line 259, in _connection_string
    data = list(self.first_database.fetch_relation_data().values())[0]
AttributeError: 'ApplicationCharm' object has no attribute 'first_database'
unit-postgresql-test-app-0: 01:52:43 ERROR unit.postgresql-test-app/0.juju-log Uncaught exception while in charm code:
Traceback (most recent call last):
  File "/var/lib/juju/agents/unit-postgresql-test-app-0/charm/./src/charm.py", line 538, in <module>
    main(ApplicationCharm)
  File "/var/lib/juju/agents/unit-postgresql-test-app-0/charm/venv/ops/main.py", line 553, in main
    manager.run()
  File "/var/lib/juju/agents/unit-postgresql-test-app-0/charm/venv/ops/main.py", line 529, in run
    self._emit()
  File "/var/lib/juju/agents/unit-postgresql-test-app-0/charm/venv/ops/main.py", line 518, in _emit
    _emit_charm_event(self.charm, self.dispatcher.event_name, self._juju_context)
  File "/var/lib/juju/agents/unit-postgresql-test-app-0/charm/venv/ops/main.py", line 139, in _emit_charm_event
    event_to_emit.emit(*args, **kwargs)
  File "/var/lib/juju/agents/unit-postgresql-test-app-0/charm/venv/ops/framework.py", line 347, in emit
    framework._emit(event)
  File "/var/lib/juju/agents/unit-postgresql-test-app-0/charm/venv/ops/framework.py", line 853, in _emit
    self._reemit(event_path)
  File "/var/lib/juju/agents/unit-postgresql-test-app-0/charm/venv/ops/framework.py", line 943, in _reemit
    custom_handler(event)
  File "/var/lib/juju/agents/unit-postgresql-test-app-0/charm/./src/charm.py", line 289, in _on_clear_continuous_writes_action
    if self._connection_string is None:
  File "/var/lib/juju/agents/unit-postgresql-test-app-0/charm/./src/charm.py", line 259, in _connection_string
    data = list(self.first_database.fetch_relation_data().values())[0]
AttributeError: 'ApplicationCharm' object has no attribute 'first_database'
unit-postgresql-test-app-0: 01:52:47 ERROR unit.postgresql-test-app/0.juju-log Uncaught exception while in charm code:
Traceback (most recent call last):
  File "/var/lib/juju/agents/unit-postgresql-test-app-0/charm/./src/charm.py", line 538, in <module>
    main(ApplicationCharm)
  File "/var/lib/juju/agents/unit-postgresql-test-app-0/charm/venv/ops/main.py", line 553, in main
    manager.run()
  File "/var/lib/juju/agents/unit-postgresql-test-app-0/charm/venv/ops/main.py", line 529, in run
    self._emit()
  File "/var/lib/juju/agents/unit-postgresql-test-app-0/charm/venv/ops/main.py", line 518, in _emit
    _emit_charm_event(self.charm, self.dispatcher.event_name, self._juju_context)
  File "/var/lib/juju/agents/unit-postgresql-test-app-0/charm/venv/ops/main.py", line 139, in _emit_charm_event
    event_to_emit.emit(*args, **kwargs)
  File "/var/lib/juju/agents/unit-postgresql-test-app-0/charm/venv/ops/framework.py", line 347, in emit
    framework._emit(event)
  File "/var/lib/juju/agents/unit-postgresql-test-app-0/charm/venv/ops/framework.py", line 853, in _emit
    self._reemit(event_path)
  File "/var/lib/juju/agents/unit-postgresql-test-app-0/charm/venv/ops/framework.py", line 943, in _reemit
    custom_handler(event)
  File "/var/lib/juju/agents/unit-postgresql-test-app-0/charm/./src/charm.py", line 289, in _on_clear_continuous_writes_action
    if self._connection_string is None:
  File "/var/lib/juju/agents/unit-postgresql-test-app-0/charm/./src/charm.py", line 259, in _connection_string
    data = list(self.first_database.fetch_relation_data().values())[0]
AttributeError: 'ApplicationCharm' object has no attribute 'first_database'
unit-postgresql-test-app-0: 01:52:51 ERROR unit.postgresql-test-app/0.juju-log Uncaught exception while in charm code:
Traceback (most recent call last):
  File "/var/lib/juju/agents/unit-postgresql-test-app-0/charm/./src/charm.py", line 538, in <module>
    main(ApplicationCharm)
  File "/var/lib/juju/agents/unit-postgresql-test-app-0/charm/venv/ops/main.py", line 553, in main
    manager.run()
  File "/var/lib/juju/agents/unit-postgresql-test-app-0/charm/venv/ops/main.py", line 529, in run
    self._emit()
  File "/var/lib/juju/agents/unit-postgresql-test-app-0/charm/venv/ops/main.py", line 518, in _emit
    _emit_charm_event(self.charm, self.dispatcher.event_name, self._juju_context)
  File "/var/lib/juju/agents/unit-postgresql-test-app-0/charm/venv/ops/main.py", line 139, in _emit_charm_event
    event_to_emit.emit(*args, **kwargs)
  File "/var/lib/juju/agents/unit-postgresql-test-app-0/charm/venv/ops/framework.py", line 347, in emit
    framework._emit(event)
  File "/var/lib/juju/agents/unit-postgresql-test-app-0/charm/venv/ops/framework.py", line 853, in _emit
    self._reemit(event_path)
  File "/var/lib/juju/agents/unit-postgresql-test-app-0/charm/venv/ops/framework.py", line 943, in _reemit
    custom_handler(event)
  File "/var/lib/juju/agents/unit-postgresql-test-app-0/charm/./src/charm.py", line 289, in _on_clear_continuous_writes_action
    if self._connection_string is None:
  File "/var/lib/juju/agents/unit-postgresql-test-app-0/charm/./src/charm.py", line 259, in _connection_string
    data = list(self.first_database.fetch_relation_data().values())[0]
AttributeError: 'ApplicationCharm' object has no attribute 'first_database'
unit-postgresql-test-app-0: 01:52:55 ERROR unit.postgresql-test-app/0.juju-log Uncaught exception while in charm code:
Traceback (most recent call last):
  File "/var/lib/juju/agents/unit-postgresql-test-app-0/charm/./src/charm.py", line 538, in <module>
    main(ApplicationCharm)
  File "/var/lib/juju/agents/unit-postgresql-test-app-0/charm/venv/ops/main.py", line 553, in main
    manager.run()
  File "/var/lib/juju/agents/unit-postgresql-test-app-0/charm/venv/ops/main.py", line 529, in run
    self._emit()
  File "/var/lib/juju/agents/unit-postgresql-test-app-0/charm/venv/ops/main.py", line 518, in _emit
    _emit_charm_event(self.charm, self.dispatcher.event_name, self._juju_context)
  File "/var/lib/juju/agents/unit-postgresql-test-app-0/charm/venv/ops/main.py", line 139, in _emit_charm_event
    event_to_emit.emit(*args, **kwargs)
  File "/var/lib/juju/agents/unit-postgresql-test-app-0/charm/venv/ops/framework.py", line 347, in emit
    framework._emit(event)
  File "/var/lib/juju/agents/unit-postgresql-test-app-0/charm/venv/ops/framework.py", line 853, in _emit
    self._reemit(event_path)
  File "/var/lib/juju/agents/unit-postgresql-test-app-0/charm/venv/ops/framework.py", line 943, in _reemit
    custom_handler(event)
  File "/var/lib/juju/agents/unit-postgresql-test-app-0/charm/./src/charm.py", line 289, in _on_clear_continuous_writes_action
    if self._connection_string is None:
  File "/var/lib/juju/agents/unit-postgresql-test-app-0/charm/./src/charm.py", line 259, in _connection_string
    data = list(self.first_database.fetch_relation_data().values())[0]
AttributeError: 'ApplicationCharm' object has no attribute 'first_database'
unit-postgresql-test-app-0: 01:52:59 ERROR unit.postgresql-test-app/0.juju-log Uncaught exception while in charm code:
Traceback (most recent call last):
  File "/var/lib/juju/agents/unit-postgresql-test-app-0/charm/./src/charm.py", line 538, in <module>
    main(ApplicationCharm)
  File "/var/lib/juju/agents/unit-postgresql-test-app-0/charm/venv/ops/main.py", line 553, in main
    manager.run()
  File "/var/lib/juju/agents/unit-postgresql-test-app-0/charm/venv/ops/main.py", line 529, in run
    self._emit()
  File "/var/lib/juju/agents/unit-postgresql-test-app-0/charm/venv/ops/main.py", line 518, in _emit
    _emit_charm_event(self.charm, self.dispatcher.event_name, self._juju_context)
  File "/var/lib/juju/agents/unit-postgresql-test-app-0/charm/venv/ops/main.py", line 139, in _emit_charm_event
    event_to_emit.emit(*args, **kwargs)
  File "/var/lib/juju/agents/unit-postgresql-test-app-0/charm/venv/ops/framework.py", line 347, in emit
    framework._emit(event)
  File "/var/lib/juju/agents/unit-postgresql-test-app-0/charm/venv/ops/framework.py", line 853, in _emit
    self._reemit(event_path)
  File "/var/lib/juju/agents/unit-postgresql-test-app-0/charm/venv/ops/framework.py", line 943, in _reemit
    custom_handler(event)
  File "/var/lib/juju/agents/unit-postgresql-test-app-0/charm/./src/charm.py", line 289, in _on_clear_continuous_writes_action
    if self._connection_string is None:
  File "/var/lib/juju/agents/unit-postgresql-test-app-0/charm/./src/charm.py", line 259, in _connection_string
    data = list(self.first_database.fetch_relation_data().values())[0]
AttributeError: 'ApplicationCharm' object has no attribute 'first_database'
unit-postgresql-test-app-0: 01:53:03 ERROR unit.postgresql-test-app/0.juju-log Uncaught exception while in charm code:
Traceback (most recent call last):
  File "/var/lib/juju/agents/unit-postgresql-test-app-0/charm/./src/charm.py", line 538, in <module>
    main(ApplicationCharm)
  File "/var/lib/juju/agents/unit-postgresql-test-app-0/charm/venv/ops/main.py", line 553, in main
    manager.run()
  File "/var/lib/juju/agents/unit-postgresql-test-app-0/charm/venv/ops/main.py", line 529, in run
    self._emit()
  File "/var/lib/juju/agents/unit-postgresql-test-app-0/charm/venv/ops/main.py", line 518, in _emit
    _emit_charm_event(self.charm, self.dispatcher.event_name, self._juju_context)
  File "/var/lib/juju/agents/unit-postgresql-test-app-0/charm/venv/ops/main.py", line 139, in _emit_charm_event
    event_to_emit.emit(*args, **kwargs)
  File "/var/lib/juju/agents/unit-postgresql-test-app-0/charm/venv/ops/framework.py", line 347, in emit
    framework._emit(event)
  File "/var/lib/juju/agents/unit-postgresql-test-app-0/charm/venv/ops/framework.py", line 853, in _emit
    self._reemit(event_path)
  File "/var/lib/juju/agents/unit-postgresql-test-app-0/charm/venv/ops/framework.py", line 943, in _reemit
    custom_handler(event)
  File "/var/lib/juju/agents/unit-postgresql-test-app-0/charm/./src/charm.py", line 289, in _on_clear_continuous_writes_action
    if self._connection_string is None:
  File "/var/lib/juju/agents/unit-postgresql-test-app-0/charm/./src/charm.py", line 259, in _connection_string
    data = list(self.first_database.fetch_relation_data().values())[0]
AttributeError: 'ApplicationCharm' object has no attribute 'first_database'
unit-postgresql-test-app-0: 01:53:07 ERROR unit.postgresql-test-app/0.juju-log Uncaught exception while in charm code:
Traceback (most recent call last):
  File "/var/lib/juju/agents/unit-postgresql-test-app-0/charm/./src/charm.py", line 538, in <module>
    main(ApplicationCharm)
  File "/var/lib/juju/agents/unit-postgresql-test-app-0/charm/venv/ops/main.py", line 553, in main
    manager.run()
  File "/var/lib/juju/agents/unit-postgresql-test-app-0/charm/venv/ops/main.py", line 529, in run
    self._emit()
  File "/var/lib/juju/agents/unit-postgresql-test-app-0/charm/venv/ops/main.py", line 518, in _emit
    _emit_charm_event(self.charm, self.dispatcher.event_name, self._juju_context)
  File "/var/lib/juju/agents/unit-postgresql-test-app-0/charm/venv/ops/main.py", line 139, in _emit_charm_event
    event_to_emit.emit(*args, **kwargs)
  File "/var/lib/juju/agents/unit-postgresql-test-app-0/charm/venv/ops/framework.py", line 347, in emit
    framework._emit(event)
  File "/var/lib/juju/agents/unit-postgresql-test-app-0/charm/venv/ops/framework.py", line 853, in _emit
    self._reemit(event_path)
  File "/var/lib/juju/agents/unit-postgresql-test-app-0/charm/venv/ops/framework.py", line 943, in _reemit
    custom_handler(event)
  File "/var/lib/juju/agents/unit-postgresql-test-app-0/charm/./src/charm.py", line 289, in _on_clear_continuous_writes_action
    if self._connection_string is None:
  File "/var/lib/juju/agents/unit-postgresql-test-app-0/charm/./src/charm.py", line 259, in _connection_string
    data = list(self.first_database.fetch_relation_data().values())[0]
AttributeError: 'ApplicationCharm' object has no attribute 'first_database'
unit-postgresql-test-app-0: 01:53:11 ERROR unit.postgresql-test-app/0.juju-log Uncaught exception while in charm code:
Traceback (most recent call last):
  File "/var/lib/juju/agents/unit-postgresql-test-app-0/charm/./src/charm.py", line 538, in <module>
    main(ApplicationCharm)
  File "/var/lib/juju/agents/unit-postgresql-test-app-0/charm/venv/ops/main.py", line 553, in main
    manager.run()
  File "/var/lib/juju/agents/unit-postgresql-test-app-0/charm/venv/ops/main.py", line 529, in run
    self._emit()
  File "/var/lib/juju/agents/unit-postgresql-test-app-0/charm/venv/ops/main.py", line 518, in _emit
    _emit_charm_event(self.charm, self.dispatcher.event_name, self._juju_context)
  File "/var/lib/juju/agents/unit-postgresql-test-app-0/charm/venv/ops/main.py", line 139, in _emit_charm_event
    event_to_emit.emit(*args, **kwargs)
  File "/var/lib/juju/agents/unit-postgresql-test-app-0/charm/venv/ops/framework.py", line 347, in emit
    framework._emit(event)
  File "/var/lib/juju/agents/unit-postgresql-test-app-0/charm/venv/ops/framework.py", line 853, in _emit
    self._reemit(event_path)
  File "/var/lib/juju/agents/unit-postgresql-test-app-0/charm/venv/ops/framework.py", line 943, in _reemit
    custom_handler(event)
  File "/var/lib/juju/agents/unit-postgresql-test-app-0/charm/./src/charm.py", line 289, in _on_clear_continuous_writes_action
    if self._connection_string is None:
  File "/var/lib/juju/agents/unit-postgresql-test-app-0/charm/./src/charm.py", line 259, in _connection_string
    data = list(self.first_database.fetch_relation_data().values())[0]
AttributeError: 'ApplicationCharm' object has no attribute 'first_database'
unit-postgresql-test-app-0: 01:53:15 ERROR unit.postgresql-test-app/0.juju-log Uncaught exception while in charm code:
Traceback (most recent call last):
  File "/var/lib/juju/agents/unit-postgresql-test-app-0/charm/./src/charm.py", line 538, in <module>
    main(ApplicationCharm)
  File "/var/lib/juju/agents/unit-postgresql-test-app-0/charm/venv/ops/main.py", line 553, in main
    manager.run()
  File "/var/lib/juju/agents/unit-postgresql-test-app-0/charm/venv/ops/main.py", line 529, in run
    self._emit()
  File "/var/lib/juju/agents/unit-postgresql-test-app-0/charm/venv/ops/main.py", line 518, in _emit
    _emit_charm_event(self.charm, self.dispatcher.event_name, self._juju_context)
  File "/var/lib/juju/agents/unit-postgresql-test-app-0/charm/venv/ops/main.py", line 139, in _emit_charm_event
    event_to_emit.emit(*args, **kwargs)
  File "/var/lib/juju/agents/unit-postgresql-test-app-0/charm/venv/ops/framework.py", line 347, in emit
    framework._emit(event)
  File "/var/lib/juju/agents/unit-postgresql-test-app-0/charm/venv/ops/framework.py", line 853, in _emit
    self._reemit(event_path)
  File "/var/lib/juju/agents/unit-postgresql-test-app-0/charm/venv/ops/framework.py", line 943, in _reemit
    custom_handler(event)
  File "/var/lib/juju/agents/unit-postgresql-test-app-0/charm/./src/charm.py", line 289, in _on_clear_continuous_writes_action
    if self._connection_string is None:
  File "/var/lib/juju/agents/unit-postgresql-test-app-0/charm/./src/charm.py", line 259, in _connection_string
    data = list(self.first_database.fetch_relation_data().values())[0]
AttributeError: 'ApplicationCharm' object has no attribute 'first_database'
unit-postgresql-test-app-0: 01:53:19 ERROR unit.postgresql-test-app/0.juju-log Uncaught exception while in charm code:
Traceback (most recent call last):
  File "/var/lib/juju/agents/unit-postgresql-test-app-0/charm/./src/charm.py", line 538, in <module>
    main(ApplicationCharm)
  File "/var/lib/juju/agents/unit-postgresql-test-app-0/charm/venv/ops/main.py", line 553, in main
    manager.run()
  File "/var/lib/juju/agents/unit-postgresql-test-app-0/charm/venv/ops/main.py", line 529, in run
    self._emit()
  File "/var/lib/juju/agents/unit-postgresql-test-app-0/charm/venv/ops/main.py", line 518, in _emit
    _emit_charm_event(self.charm, self.dispatcher.event_name, self._juju_context)
  File "/var/lib/juju/agents/unit-postgresql-test-app-0/charm/venv/ops/main.py", line 139, in _emit_charm_event
    event_to_emit.emit(*args, **kwargs)
  File "/var/lib/juju/agents/unit-postgresql-test-app-0/charm/venv/ops/framework.py", line 347, in emit
    framework._emit(event)
  File "/var/lib/juju/agents/unit-postgresql-test-app-0/charm/venv/ops/framework.py", line 853, in _emit
    self._reemit(event_path)
  File "/var/lib/juju/agents/unit-postgresql-test-app-0/charm/venv/ops/framework.py", line 943, in _reemit
    custom_handler(event)
  File "/var/lib/juju/agents/unit-postgresql-test-app-0/charm/./src/charm.py", line 289, in _on_clear_continuous_writes_action
    if self._connection_string is None:
  File "/var/lib/juju/agents/unit-postgresql-test-app-0/charm/./src/charm.py", line 259, in _connection_string
    data = list(self.first_database.fetch_relation_data().values())[0]
AttributeError: 'ApplicationCharm' object has no attribute 'first_database'
unit-postgresql-test-app-0: 01:53:23 ERROR unit.postgresql-test-app/0.juju-log Uncaught exception while in charm code:
Traceback (most recent call last):
  File "/var/lib/juju/agents/unit-postgresql-test-app-0/charm/./src/charm.py", line 538, in <module>
    main(ApplicationCharm)
  File "/var/lib/juju/agents/unit-postgresql-test-app-0/charm/venv/ops/main.py", line 553, in main
    manager.run()
  File "/var/lib/juju/agents/unit-postgresql-test-app-0/charm/venv/ops/main.py", line 529, in run
    self._emit()
  File "/var/lib/juju/agents/unit-postgresql-test-app-0/charm/venv/ops/main.py", line 518, in _emit
    _emit_charm_event(self.charm, self.dispatcher.event_name, self._juju_context)
  File "/var/lib/juju/agents/unit-postgresql-test-app-0/charm/venv/ops/main.py", line 139, in _emit_charm_event
    event_to_emit.emit(*args, **kwargs)
  File "/var/lib/juju/agents/unit-postgresql-test-app-0/charm/venv/ops/framework.py", line 347, in emit
    framework._emit(event)
  File "/var/lib/juju/agents/unit-postgresql-test-app-0/charm/venv/ops/framework.py", line 853, in _emit
    self._reemit(event_path)
  File "/var/lib/juju/agents/unit-postgresql-test-app-0/charm/venv/ops/framework.py", line 943, in _reemit
    custom_handler(event)
  File "/var/lib/juju/agents/unit-postgresql-test-app-0/charm/./src/charm.py", line 289, in _on_clear_continuous_writes_action
    if self._connection_string is None:
  File "/var/lib/juju/agents/unit-postgresql-test-app-0/charm/./src/charm.py", line 259, in _connection_string
    data = list(self.first_database.fetch_relation_data().values())[0]
AttributeError: 'ApplicationCharm' object has no attribute 'first_database'
unit-postgresql-test-app-0: 01:53:27 ERROR unit.postgresql-test-app/0.juju-log Uncaught exception while in charm code:
Traceback (most recent call last):
  File "/var/lib/juju/agents/unit-postgresql-test-app-0/charm/./src/charm.py", line 538, in <module>
    main(ApplicationCharm)
  File "/var/lib/juju/agents/unit-postgresql-test-app-0/charm/venv/ops/main.py", line 553, in main
    manager.run()
  File "/var/lib/juju/agents/unit-postgresql-test-app-0/charm/venv/ops/main.py", line 529, in run
    self._emit()
  File "/var/lib/juju/agents/unit-postgresql-test-app-0/charm/venv/ops/main.py", line 518, in _emit
    _emit_charm_event(self.charm, self.dispatcher.event_name, self._juju_context)
  File "/var/lib/juju/agents/unit-postgresql-test-app-0/charm/venv/ops/main.py", line 139, in _emit_charm_event
    event_to_emit.emit(*args, **kwargs)
  File "/var/lib/juju/agents/unit-postgresql-test-app-0/charm/venv/ops/framework.py", line 347, in emit
    framework._emit(event)
  File "/var/lib/juju/agents/unit-postgresql-test-app-0/charm/venv/ops/framework.py", line 853, in _emit
    self._reemit(event_path)
  File "/var/lib/juju/agents/unit-postgresql-test-app-0/charm/venv/ops/framework.py", line 943, in _reemit
    custom_handler(event)
  File "/var/lib/juju/agents/unit-postgresql-test-app-0/charm/./src/charm.py", line 289, in _on_clear_continuous_writes_action
    if self._connection_string is None:
  File "/var/lib/juju/agents/unit-postgresql-test-app-0/charm/./src/charm.py", line 259, in _connection_string
    data = list(self.first_database.fetch_relation_data().values())[0]
AttributeError: 'ApplicationCharm' object has no attribute 'first_database'
unit-postgresql-test-app-0: 01:53:31 ERROR unit.postgresql-test-app/0.juju-log Uncaught exception while in charm code:
Traceback (most recent call last):
  File "/var/lib/juju/agents/unit-postgresql-test-app-0/charm/./src/charm.py", line 538, in <module>
    main(ApplicationCharm)
  File "/var/lib/juju/agents/unit-postgresql-test-app-0/charm/venv/ops/main.py", line 553, in main
    manager.run()
  File "/var/lib/juju/agents/unit-postgresql-test-app-0/charm/venv/ops/main.py", line 529, in run
    self._emit()
  File "/var/lib/juju/agents/unit-postgresql-test-app-0/charm/venv/ops/main.py", line 518, in _emit
    _emit_charm_event(self.charm, self.dispatcher.event_name, self._juju_context)
  File "/var/lib/juju/agents/unit-postgresql-test-app-0/charm/venv/ops/main.py", line 139, in _emit_charm_event
    event_to_emit.emit(*args, **kwargs)
  File "/var/lib/juju/agents/unit-postgresql-test-app-0/charm/venv/ops/framework.py", line 347, in emit
    framework._emit(event)
  File "/var/lib/juju/agents/unit-postgresql-test-app-0/charm/venv/ops/framework.py", line 853, in _emit
    self._reemit(event_path)
  File "/var/lib/juju/agents/unit-postgresql-test-app-0/charm/venv/ops/framework.py", line 943, in _reemit
    custom_handler(event)
  File "/var/lib/juju/agents/unit-postgresql-test-app-0/charm/./src/charm.py", line 289, in _on_clear_continuous_writes_action
    if self._connection_string is None:
  File "/var/lib/juju/agents/unit-postgresql-test-app-0/charm/./src/charm.py", line 259, in _connection_string
    data = list(self.first_database.fetch_relation_data().values())[0]
AttributeError: 'ApplicationCharm' object has no attribute 'first_database'
unit-postgresql-test-app-0: 01:53:35 ERROR unit.postgresql-test-app/0.juju-log Uncaught exception while in charm code:
Traceback (most recent call last):
  File "/var/lib/juju/agents/unit-postgresql-test-app-0/charm/./src/charm.py", line 538, in <module>
    main(ApplicationCharm)
  File "/var/lib/juju/agents/unit-postgresql-test-app-0/charm/venv/ops/main.py", line 553, in main
    manager.run()
  File "/var/lib/juju/agents/unit-postgresql-test-app-0/charm/venv/ops/main.py", line 529, in run
    self._emit()
  File "/var/lib/juju/agents/unit-postgresql-test-app-0/charm/venv/ops/main.py", line 518, in _emit
    _emit_charm_event(self.charm, self.dispatcher.event_name, self._juju_context)
  File "/var/lib/juju/agents/unit-postgresql-test-app-0/charm/venv/ops/main.py", line 139, in _emit_charm_event
    event_to_emit.emit(*args, **kwargs)
  File "/var/lib/juju/agents/unit-postgresql-test-app-0/charm/venv/ops/framework.py", line 347, in emit
    framework._emit(event)
  File "/var/lib/juju/agents/unit-postgresql-test-app-0/charm/venv/ops/framework.py", line 853, in _emit
    self._reemit(event_path)
  File "/var/lib/juju/agents/unit-postgresql-test-app-0/charm/venv/ops/framework.py", line 943, in _reemit
    custom_handler(event)
  File "/var/lib/juju/agents/unit-postgresql-test-app-0/charm/./src/charm.py", line 289, in _on_clear_continuous_writes_action
    if self._connection_string is None:
  File "/var/lib/juju/agents/unit-postgresql-test-app-0/charm/./src/charm.py", line 259, in _connection_string
    data = list(self.first_database.fetch_relation_data().values())[0]
AttributeError: 'ApplicationCharm' object has no attribute 'first_database'
unit-postgresql-test-app-0: 01:53:39 ERROR unit.postgresql-test-app/0.juju-log Uncaught exception while in charm code:
Traceback (most recent call last):
  File "/var/lib/juju/agents/unit-postgresql-test-app-0/charm/./src/charm.py", line 538, in <module>
    main(ApplicationCharm)
  File "/var/lib/juju/agents/unit-postgresql-test-app-0/charm/venv/ops/main.py", line 553, in main
    manager.run()
  File "/var/lib/juju/agents/unit-postgresql-test-app-0/charm/venv/ops/main.py", line 529, in run
    self._emit()
  File "/var/lib/juju/agents/unit-postgresql-test-app-0/charm/venv/ops/main.py", line 518, in _emit
    _emit_charm_event(self.charm, self.dispatcher.event_name, self._juju_context)
  File "/var/lib/juju/agents/unit-postgresql-test-app-0/charm/venv/ops/main.py", line 139, in _emit_charm_event
    event_to_emit.emit(*args, **kwargs)
  File "/var/lib/juju/agents/unit-postgresql-test-app-0/charm/venv/ops/framework.py", line 347, in emit
    framework._emit(event)
  File "/var/lib/juju/agents/unit-postgresql-test-app-0/charm/venv/ops/framework.py", line 853, in _emit
    self._reemit(event_path)
  File "/var/lib/juju/agents/unit-postgresql-test-app-0/charm/venv/ops/framework.py", line 943, in _reemit
    custom_handler(event)
  File "/var/lib/juju/agents/unit-postgresql-test-app-0/charm/./src/charm.py", line 289, in _on_clear_continuous_writes_action
    if self._connection_string is None:
  File "/var/lib/juju/agents/unit-postgresql-test-app-0/charm/./src/charm.py", line 259, in _connection_string
    data = list(self.first_database.fetch_relation_data().values())[0]
AttributeError: 'ApplicationCharm' object has no attribute 'first_database'
unit-postgresql-test-app-0: 01:53:43 ERROR unit.postgresql-test-app/0.juju-log Uncaught exception while in charm code:
Traceback (most recent call last):
  File "/var/lib/juju/agents/unit-postgresql-test-app-0/charm/./src/charm.py", line 538, in <module>
    main(ApplicationCharm)
  File "/var/lib/juju/agents/unit-postgresql-test-app-0/charm/venv/ops/main.py", line 553, in main
    manager.run()
  File "/var/lib/juju/agents/unit-postgresql-test-app-0/charm/venv/ops/main.py", line 529, in run
    self._emit()
  File "/var/lib/juju/agents/unit-postgresql-test-app-0/charm/venv/ops/main.py", line 518, in _emit
    _emit_charm_event(self.charm, self.dispatcher.event_name, self._juju_context)
  File "/var/lib/juju/agents/unit-postgresql-test-app-0/charm/venv/ops/main.py", line 139, in _emit_charm_event
    event_to_emit.emit(*args, **kwargs)
  File "/var/lib/juju/agents/unit-postgresql-test-app-0/charm/venv/ops/framework.py", line 347, in emit
    framework._emit(event)
  File "/var/lib/juju/agents/unit-postgresql-test-app-0/charm/venv/ops/framework.py", line 853, in _emit
    self._reemit(event_path)
  File "/var/lib/juju/agents/unit-postgresql-test-app-0/charm/venv/ops/framework.py", line 943, in _reemit
    custom_handler(event)
  File "/var/lib/juju/agents/unit-postgresql-test-app-0/charm/./src/charm.py", line 289, in _on_clear_continuous_writes_action
    if self._connection_string is None:
  File "/var/lib/juju/agents/unit-postgresql-test-app-0/charm/./src/charm.py", line 259, in _connection_string
    data = list(self.first_database.fetch_relation_data().values())[0]
AttributeError: 'ApplicationCharm' object has no attribute 'first_database'
unit-postgresql-test-app-0: 01:53:47 ERROR unit.postgresql-test-app/0.juju-log Uncaught exception while in charm code:
Traceback (most recent call last):
  File "/var/lib/juju/agents/unit-postgresql-test-app-0/charm/./src/charm.py", line 538, in <module>
    main(ApplicationCharm)
  File "/var/lib/juju/agents/unit-postgresql-test-app-0/charm/venv/ops/main.py", line 553, in main
    manager.run()
  File "/var/lib/juju/agents/unit-postgresql-test-app-0/charm/venv/ops/main.py", line 529, in run
    self._emit()
  File "/var/lib/juju/agents/unit-postgresql-test-app-0/charm/venv/ops/main.py", line 518, in _emit
    _emit_charm_event(self.charm, self.dispatcher.event_name, self._juju_context)
  File "/var/lib/juju/agents/unit-postgresql-test-app-0/charm/venv/ops/main.py", line 139, in _emit_charm_event
    event_to_emit.emit(*args, **kwargs)
  File "/var/lib/juju/agents/unit-postgresql-test-app-0/charm/venv/ops/framework.py", line 347, in emit
    framework._emit(event)
  File "/var/lib/juju/agents/unit-postgresql-test-app-0/charm/venv/ops/framework.py", line 853, in _emit
    self._reemit(event_path)
  File "/var/lib/juju/agents/unit-postgresql-test-app-0/charm/venv/ops/framework.py", line 943, in _reemit
    custom_handler(event)
  File "/var/lib/juju/agents/unit-postgresql-test-app-0/charm/./src/charm.py", line 289, in _on_clear_continuous_writes_action
    if self._connection_string is None:
  File "/var/lib/juju/agents/unit-postgresql-test-app-0/charm/./src/charm.py", line 259, in _connection_string
    data = list(self.first_database.fetch_relation_data().values())[0]
AttributeError: 'ApplicationCharm' object has no attribute 'first_database'
unit-postgresql-test-app-0: 01:53:51 ERROR unit.postgresql-test-app/0.juju-log Uncaught exception while in charm code:
Traceback (most recent call last):
  File "/var/lib/juju/agents/unit-postgresql-test-app-0/charm/./src/charm.py", line 538, in <module>
    main(ApplicationCharm)
  File "/var/lib/juju/agents/unit-postgresql-test-app-0/charm/venv/ops/main.py", line 553, in main
    manager.run()
  File "/var/lib/juju/agents/unit-postgresql-test-app-0/charm/venv/ops/main.py", line 529, in run
    self._emit()
  File "/var/lib/juju/agents/unit-postgresql-test-app-0/charm/venv/ops/main.py", line 518, in _emit
    _emit_charm_event(self.charm, self.dispatcher.event_name, self._juju_context)
  File "/var/lib/juju/agents/unit-postgresql-test-app-0/charm/venv/ops/main.py", line 139, in _emit_charm_event
    event_to_emit.emit(*args, **kwargs)
  File "/var/lib/juju/agents/unit-postgresql-test-app-0/charm/venv/ops/framework.py", line 347, in emit
    framework._emit(event)
  File "/var/lib/juju/agents/unit-postgresql-test-app-0/charm/venv/ops/framework.py", line 853, in _emit
    self._reemit(event_path)
  File "/var/lib/juju/agents/unit-postgresql-test-app-0/charm/venv/ops/framework.py", line 943, in _reemit
    custom_handler(event)
  File "/var/lib/juju/agents/unit-postgresql-test-app-0/charm/./src/charm.py", line 289, in _on_clear_continuous_writes_action
    if self._connection_string is None:
  File "/var/lib/juju/agents/unit-postgresql-test-app-0/charm/./src/charm.py", line 259, in _connection_string
    data = list(self.first_database.fetch_relation_data().values())[0]
AttributeError: 'ApplicationCharm' object has no attribute 'first_database'
unit-postgresql-test-app-0: 01:53:55 ERROR unit.postgresql-test-app/0.juju-log Uncaught exception while in charm code:
Traceback (most recent call last):
  File "/var/lib/juju/agents/unit-postgresql-test-app-0/charm/./src/charm.py", line 538, in <module>
    main(ApplicationCharm)
  File "/var/lib/juju/agents/unit-postgresql-test-app-0/charm/venv/ops/main.py", line 553, in main
    manager.run()
  File "/var/lib/juju/agents/unit-postgresql-test-app-0/charm/venv/ops/main.py", line 529, in run
    self._emit()
  File "/var/lib/juju/agents/unit-postgresql-test-app-0/charm/venv/ops/main.py", line 518, in _emit
    _emit_charm_event(self.charm, self.dispatcher.event_name, self._juju_context)
  File "/var/lib/juju/agents/unit-postgresql-test-app-0/charm/venv/ops/main.py", line 139, in _emit_charm_event
    event_to_emit.emit(*args, **kwargs)
  File "/var/lib/juju/agents/unit-postgresql-test-app-0/charm/venv/ops/framework.py", line 347, in emit
    framework._emit(event)
  File "/var/lib/juju/agents/unit-postgresql-test-app-0/charm/venv/ops/framework.py", line 853, in _emit
    self._reemit(event_path)
  File "/var/lib/juju/agents/unit-postgresql-test-app-0/charm/venv/ops/framework.py", line 943, in _reemit
    custom_handler(event)
  File "/var/lib/juju/agents/unit-postgresql-test-app-0/charm/./src/charm.py", line 289, in _on_clear_continuous_writes_action
    if self._connection_string is None:
  File "/var/lib/juju/agents/unit-postgresql-test-app-0/charm/./src/charm.py", line 259, in _connection_string
    data = list(self.first_database.fetch_relation_data().values())[0]
AttributeError: 'ApplicationCharm' object has no attribute 'first_database'
unit-postgresql-test-app-0: 01:53:59 ERROR unit.postgresql-test-app/0.juju-log Uncaught exception while in charm code:
Traceback (most recent call last):
  File "/var/lib/juju/agents/unit-postgresql-test-app-0/charm/./src/charm.py", line 538, in <module>
    main(ApplicationCharm)
  File "/var/lib/juju/agents/unit-postgresql-test-app-0/charm/venv/ops/main.py", line 553, in main
    manager.run()
  File "/var/lib/juju/agents/unit-postgresql-test-app-0/charm/venv/ops/main.py", line 529, in run
    self._emit()
  File "/var/lib/juju/agents/unit-postgresql-test-app-0/charm/venv/ops/main.py", line 518, in _emit
    _emit_charm_event(self.charm, self.dispatcher.event_name, self._juju_context)
  File "/var/lib/juju/agents/unit-postgresql-test-app-0/charm/venv/ops/main.py", line 139, in _emit_charm_event
    event_to_emit.emit(*args, **kwargs)
  File "/var/lib/juju/agents/unit-postgresql-test-app-0/charm/venv/ops/framework.py", line 347, in emit
    framework._emit(event)
  File "/var/lib/juju/agents/unit-postgresql-test-app-0/charm/venv/ops/framework.py", line 853, in _emit
    self._reemit(event_path)
  File "/var/lib/juju/agents/unit-postgresql-test-app-0/charm/venv/ops/framework.py", line 943, in _reemit
    custom_handler(event)
  File "/var/lib/juju/agents/unit-postgresql-test-app-0/charm/./src/charm.py", line 289, in _on_clear_continuous_writes_action
    if self._connection_string is None:
  File "/var/lib/juju/agents/unit-postgresql-test-app-0/charm/./src/charm.py", line 259, in _connection_string
    data = list(self.first_database.fetch_relation_data().values())[0]
AttributeError: 'ApplicationCharm' object has no attribute 'first_database'
unit-postgresql-test-app-0: 01:54:03 ERROR unit.postgresql-test-app/0.juju-log Uncaught exception while in charm code:
Traceback (most recent call last):
  File "/var/lib/juju/agents/unit-postgresql-test-app-0/charm/./src/charm.py", line 538, in <module>
    main(ApplicationCharm)
  File "/var/lib/juju/agents/unit-postgresql-test-app-0/charm/venv/ops/main.py", line 553, in main
    manager.run()
  File "/var/lib/juju/agents/unit-postgresql-test-app-0/charm/venv/ops/main.py", line 529, in run
    self._emit()
  File "/var/lib/juju/agents/unit-postgresql-test-app-0/charm/venv/ops/main.py", line 518, in _emit
    _emit_charm_event(self.charm, self.dispatcher.event_name, self._juju_context)
  File "/var/lib/juju/agents/unit-postgresql-test-app-0/charm/venv/ops/main.py", line 139, in _emit_charm_event
    event_to_emit.emit(*args, **kwargs)
  File "/var/lib/juju/agents/unit-postgresql-test-app-0/charm/venv/ops/framework.py", line 347, in emit
    framework._emit(event)
  File "/var/lib/juju/agents/unit-postgresql-test-app-0/charm/venv/ops/framework.py", line 853, in _emit
    self._reemit(event_path)
  File "/var/lib/juju/agents/unit-postgresql-test-app-0/charm/venv/ops/framework.py", line 943, in _reemit
    custom_handler(event)
  File "/var/lib/juju/agents/unit-postgresql-test-app-0/charm/./src/charm.py", line 289, in _on_clear_continuous_writes_action
    if self._connection_string is None:
  File "/var/lib/juju/agents/unit-postgresql-test-app-0/charm/./src/charm.py", line 259, in _connection_string
    data = list(self.first_database.fetch_relation_data().values())[0]
AttributeError: 'ApplicationCharm' object has no attribute 'first_database'
unit-postgresql-test-app-0: 01:54:07 ERROR unit.postgresql-test-app/0.juju-log Uncaught exception while in charm code:
Traceback (most recent call last):
  File "/var/lib/juju/agents/unit-postgresql-test-app-0/charm/./src/charm.py", line 538, in <module>
    main(ApplicationCharm)
  File "/var/lib/juju/agents/unit-postgresql-test-app-0/charm/venv/ops/main.py", line 553, in main
    manager.run()
  File "/var/lib/juju/agents/unit-postgresql-test-app-0/charm/venv/ops/main.py", line 529, in run
    self._emit()
  File "/var/lib/juju/agents/unit-postgresql-test-app-0/charm/venv/ops/main.py", line 518, in _emit
    _emit_charm_event(self.charm, self.dispatcher.event_name, self._juju_context)
  File "/var/lib/juju/agents/unit-postgresql-test-app-0/charm/venv/ops/main.py", line 139, in _emit_charm_event
    event_to_emit.emit(*args, **kwargs)
  File "/var/lib/juju/agents/unit-postgresql-test-app-0/charm/venv/ops/framework.py", line 347, in emit
    framework._emit(event)
  File "/var/lib/juju/agents/unit-postgresql-test-app-0/charm/venv/ops/framework.py", line 853, in _emit
    self._reemit(event_path)
  File "/var/lib/juju/agents/unit-postgresql-test-app-0/charm/venv/ops/framework.py", line 943, in _reemit
    custom_handler(event)
  File "/var/lib/juju/agents/unit-postgresql-test-app-0/charm/./src/charm.py", line 289, in _on_clear_continuous_writes_action
    if self._connection_string is None:
  File "/var/lib/juju/agents/unit-postgresql-test-app-0/charm/./src/charm.py", line 259, in _connection_string
    data = list(self.first_database.fetch_relation_data().values())[0]
AttributeError: 'ApplicationCharm' object has no attribute 'first_database'
unit-postgresql-test-app-0: 01:54:12 ERROR unit.postgresql-test-app/0.juju-log Uncaught exception while in charm code:
Traceback (most recent call last):
  File "/var/lib/juju/agents/unit-postgresql-test-app-0/charm/./src/charm.py", line 538, in <module>
    main(ApplicationCharm)
  File "/var/lib/juju/agents/unit-postgresql-test-app-0/charm/venv/ops/main.py", line 553, in main
    manager.run()
  File "/var/lib/juju/agents/unit-postgresql-test-app-0/charm/venv/ops/main.py", line 529, in run
    self._emit()
  File "/var/lib/juju/agents/unit-postgresql-test-app-0/charm/venv/ops/main.py", line 518, in _emit
    _emit_charm_event(self.charm, self.dispatcher.event_name, self._juju_context)
  File "/var/lib/juju/agents/unit-postgresql-test-app-0/charm/venv/ops/main.py", line 139, in _emit_charm_event
    event_to_emit.emit(*args, **kwargs)
  File "/var/lib/juju/agents/unit-postgresql-test-app-0/charm/venv/ops/framework.py", line 347, in emit
    framework._emit(event)
  File "/var/lib/juju/agents/unit-postgresql-test-app-0/charm/venv/ops/framework.py", line 853, in _emit
    self._reemit(event_path)
  File "/var/lib/juju/agents/unit-postgresql-test-app-0/charm/venv/ops/framework.py", line 943, in _reemit
    custom_handler(event)
  File "/var/lib/juju/agents/unit-postgresql-test-app-0/charm/./src/charm.py", line 289, in _on_clear_continuous_writes_action
    if self._connection_string is None:
  File "/var/lib/juju/agents/unit-postgresql-test-app-0/charm/./src/charm.py", line 259, in _connection_string
    data = list(self.first_database.fetch_relation_data().values())[0]
AttributeError: 'ApplicationCharm' object has no attribute 'first_database'
unit-postgresql-test-app-0: 01:54:16 ERROR unit.postgresql-test-app/0.juju-log Uncaught exception while in charm code:
Traceback (most recent call last):
  File "/var/lib/juju/agents/unit-postgresql-test-app-0/charm/./src/charm.py", line 538, in <module>
    main(ApplicationCharm)
  File "/var/lib/juju/agents/unit-postgresql-test-app-0/charm/venv/ops/main.py", line 553, in main
    manager.run()
  File "/var/lib/juju/agents/unit-postgresql-test-app-0/charm/venv/ops/main.py", line 529, in run
    self._emit()
  File "/var/lib/juju/agents/unit-postgresql-test-app-0/charm/venv/ops/main.py", line 518, in _emit
    _emit_charm_event(self.charm, self.dispatcher.event_name, self._juju_context)
  File "/var/lib/juju/agents/unit-postgresql-test-app-0/charm/venv/ops/main.py", line 139, in _emit_charm_event
    event_to_emit.emit(*args, **kwargs)
  File "/var/lib/juju/agents/unit-postgresql-test-app-0/charm/venv/ops/framework.py", line 347, in emit
    framework._emit(event)
  File "/var/lib/juju/agents/unit-postgresql-test-app-0/charm/venv/ops/framework.py", line 853, in _emit
    self._reemit(event_path)
  File "/var/lib/juju/agents/unit-postgresql-test-app-0/charm/venv/ops/framework.py", line 943, in _reemit
    custom_handler(event)
  File "/var/lib/juju/agents/unit-postgresql-test-app-0/charm/./src/charm.py", line 289, in _on_clear_continuous_writes_action
    if self._connection_string is None:
  File "/var/lib/juju/agents/unit-postgresql-test-app-0/charm/./src/charm.py", line 259, in _connection_string
    data = list(self.first_database.fetch_relation_data().values())[0]
AttributeError: 'ApplicationCharm' object has no attribute 'first_database'
unit-postgresql-test-app-0: 01:54:20 ERROR unit.postgresql-test-app/0.juju-log Uncaught exception while in charm code:
Traceback (most recent call last):
  File "/var/lib/juju/agents/unit-postgresql-test-app-0/charm/./src/charm.py", line 538, in <module>
    main(ApplicationCharm)
  File "/var/lib/juju/agents/unit-postgresql-test-app-0/charm/venv/ops/main.py", line 553, in main
    manager.run()
  File "/var/lib/juju/agents/unit-postgresql-test-app-0/charm/venv/ops/main.py", line 529, in run
    self._emit()
  File "/var/lib/juju/agents/unit-postgresql-test-app-0/charm/venv/ops/main.py", line 518, in _emit
    _emit_charm_event(self.charm, self.dispatcher.event_name, self._juju_context)
  File "/var/lib/juju/agents/unit-postgresql-test-app-0/charm/venv/ops/main.py", line 139, in _emit_charm_event
    event_to_emit.emit(*args, **kwargs)
  File "/var/lib/juju/agents/unit-postgresql-test-app-0/charm/venv/ops/framework.py", line 347, in emit
    framework._emit(event)
  File "/var/lib/juju/agents/unit-postgresql-test-app-0/charm/venv/ops/framework.py", line 853, in _emit
    self._reemit(event_path)
  File "/var/lib/juju/agents/unit-postgresql-test-app-0/charm/venv/ops/framework.py", line 943, in _reemit
    custom_handler(event)
  File "/var/lib/juju/agents/unit-postgresql-test-app-0/charm/./src/charm.py", line 289, in _on_clear_continuous_writes_action
    if self._connection_string is None:
  File "/var/lib/juju/agents/unit-postgresql-test-app-0/charm/./src/charm.py", line 259, in _connection_string
    data = list(self.first_database.fetch_relation_data().values())[0]
AttributeError: 'ApplicationCharm' object has no attribute 'first_database'
unit-postgresql-test-app-0: 01:54:24 ERROR unit.postgresql-test-app/0.juju-log Uncaught exception while in charm code:
Traceback (most recent call last):
  File "/var/lib/juju/agents/unit-postgresql-test-app-0/charm/./src/charm.py", line 538, in <module>
    main(ApplicationCharm)
  File "/var/lib/juju/agents/unit-postgresql-test-app-0/charm/venv/ops/main.py", line 553, in main
    manager.run()
  File "/var/lib/juju/agents/unit-postgresql-test-app-0/charm/venv/ops/main.py", line 529, in run
    self._emit()
  File "/var/lib/juju/agents/unit-postgresql-test-app-0/charm/venv/ops/main.py", line 518, in _emit
    _emit_charm_event(self.charm, self.dispatcher.event_name, self._juju_context)
  File "/var/lib/juju/agents/unit-postgresql-test-app-0/charm/venv/ops/main.py", line 139, in _emit_charm_event
    event_to_emit.emit(*args, **kwargs)
  File "/var/lib/juju/agents/unit-postgresql-test-app-0/charm/venv/ops/framework.py", line 347, in emit
    framework._emit(event)
  File "/var/lib/juju/agents/unit-postgresql-test-app-0/charm/venv/ops/framework.py", line 853, in _emit
    self._reemit(event_path)
  File "/var/lib/juju/agents/unit-postgresql-test-app-0/charm/venv/ops/framework.py", line 943, in _reemit
    custom_handler(event)
  File "/var/lib/juju/agents/unit-postgresql-test-app-0/charm/./src/charm.py", line 289, in _on_clear_continuous_writes_action
    if self._connection_string is None:
  File "/var/lib/juju/agents/unit-postgresql-test-app-0/charm/./src/charm.py", line 259, in _connection_string
    data = list(self.first_database.fetch_relation_data().values())[0]
AttributeError: 'ApplicationCharm' object has no attribute 'first_database'
unit-postgresql-test-app-0: 01:54:28 ERROR unit.postgresql-test-app/0.juju-log Uncaught exception while in charm code:
Traceback (most recent call last):
  File "/var/lib/juju/agents/unit-postgresql-test-app-0/charm/./src/charm.py", line 538, in <module>
    main(ApplicationCharm)
  File "/var/lib/juju/agents/unit-postgresql-test-app-0/charm/venv/ops/main.py", line 553, in main
    manager.run()
  File "/var/lib/juju/agents/unit-postgresql-test-app-0/charm/venv/ops/main.py", line 529, in run
    self._emit()
  File "/var/lib/juju/agents/unit-postgresql-test-app-0/charm/venv/ops/main.py", line 518, in _emit
    _emit_charm_event(self.charm, self.dispatcher.event_name, self._juju_context)
  File "/var/lib/juju/agents/unit-postgresql-test-app-0/charm/venv/ops/main.py", line 139, in _emit_charm_event
    event_to_emit.emit(*args, **kwargs)
  File "/var/lib/juju/agents/unit-postgresql-test-app-0/charm/venv/ops/framework.py", line 347, in emit
    framework._emit(event)
  File "/var/lib/juju/agents/unit-postgresql-test-app-0/charm/venv/ops/framework.py", line 853, in _emit
    self._reemit(event_path)
  File "/var/lib/juju/agents/unit-postgresql-test-app-0/charm/venv/ops/framework.py", line 943, in _reemit
    custom_handler(event)
  File "/var/lib/juju/agents/unit-postgresql-test-app-0/charm/./src/charm.py", line 289, in _on_clear_continuous_writes_action
    if self._connection_string is None:
  File "/var/lib/juju/agents/unit-postgresql-test-app-0/charm/./src/charm.py", line 259, in _connection_string
    data = list(self.first_database.fetch_relation_data().values())[0]
AttributeError: 'ApplicationCharm' object has no attribute 'first_database'
unit-postgresql-test-app-0: 01:54:32 ERROR unit.postgresql-test-app/0.juju-log Uncaught exception while in charm code:
Traceback (most recent call last):
  File "/var/lib/juju/agents/unit-postgresql-test-app-0/charm/./src/charm.py", line 538, in <module>
    main(ApplicationCharm)
  File "/var/lib/juju/agents/unit-postgresql-test-app-0/charm/venv/ops/main.py", line 553, in main
    manager.run()
  File "/var/lib/juju/agents/unit-postgresql-test-app-0/charm/venv/ops/main.py", line 529, in run
    self._emit()
  File "/var/lib/juju/agents/unit-postgresql-test-app-0/charm/venv/ops/main.py", line 518, in _emit
    _emit_charm_event(self.charm, self.dispatcher.event_name, self._juju_context)
  File "/var/lib/juju/agents/unit-postgresql-test-app-0/charm/venv/ops/main.py", line 139, in _emit_charm_event
    event_to_emit.emit(*args, **kwargs)
  File "/var/lib/juju/agents/unit-postgresql-test-app-0/charm/venv/ops/framework.py", line 347, in emit
    framework._emit(event)
  File "/var/lib/juju/agents/unit-postgresql-test-app-0/charm/venv/ops/framework.py", line 853, in _emit
    self._reemit(event_path)
  File "/var/lib/juju/agents/unit-postgresql-test-app-0/charm/venv/ops/framework.py", line 943, in _reemit
    custom_handler(event)
  File "/var/lib/juju/agents/unit-postgresql-test-app-0/charm/./src/charm.py", line 289, in _on_clear_continuous_writes_action
    if self._connection_string is None:
  File "/var/lib/juju/agents/unit-postgresql-test-app-0/charm/./src/charm.py", line 259, in _connection_string
    data = list(self.first_database.fetch_relation_data().values())[0]
AttributeError: 'ApplicationCharm' object has no attribute 'first_database'
unit-postgresql-test-app-0: 01:54:36 ERROR unit.postgresql-test-app/0.juju-log Uncaught exception while in charm code:
Traceback (most recent call last):
  File "/var/lib/juju/agents/unit-postgresql-test-app-0/charm/./src/charm.py", line 538, in <module>
    main(ApplicationCharm)
  File "/var/lib/juju/agents/unit-postgresql-test-app-0/charm/venv/ops/main.py", line 553, in main
    manager.run()
  File "/var/lib/juju/agents/unit-postgresql-test-app-0/charm/venv/ops/main.py", line 529, in run
    self._emit()
  File "/var/lib/juju/agents/unit-postgresql-test-app-0/charm/venv/ops/main.py", line 518, in _emit
    _emit_charm_event(self.charm, self.dispatcher.event_name, self._juju_context)
  File "/var/lib/juju/agents/unit-postgresql-test-app-0/charm/venv/ops/main.py", line 139, in _emit_charm_event
    event_to_emit.emit(*args, **kwargs)
  File "/var/lib/juju/agents/unit-postgresql-test-app-0/charm/venv/ops/framework.py", line 347, in emit
    framework._emit(event)
  File "/var/lib/juju/agents/unit-postgresql-test-app-0/charm/venv/ops/framework.py", line 853, in _emit
    self._reemit(event_path)
  File "/var/lib/juju/agents/unit-postgresql-test-app-0/charm/venv/ops/framework.py", line 943, in _reemit
    custom_handler(event)
  File "/var/lib/juju/agents/unit-postgresql-test-app-0/charm/./src/charm.py", line 289, in _on_clear_continuous_writes_action
    if self._connection_string is None:
  File "/var/lib/juju/agents/unit-postgresql-test-app-0/charm/./src/charm.py", line 259, in _connection_string
    data = list(self.first_database.fetch_relation_data().values())[0]
AttributeError: 'ApplicationCharm' object has no attribute 'first_database'
unit-postgresql-test-app-0: 01:54:40 ERROR unit.postgresql-test-app/0.juju-log Uncaught exception while in charm code:
Traceback (most recent call last):
  File "/var/lib/juju/agents/unit-postgresql-test-app-0/charm/./src/charm.py", line 538, in <module>
    main(ApplicationCharm)
  File "/var/lib/juju/agents/unit-postgresql-test-app-0/charm/venv/ops/main.py", line 553, in main
    manager.run()
  File "/var/lib/juju/agents/unit-postgresql-test-app-0/charm/venv/ops/main.py", line 529, in run
    self._emit()
  File "/var/lib/juju/agents/unit-postgresql-test-app-0/charm/venv/ops/main.py", line 518, in _emit
    _emit_charm_event(self.charm, self.dispatcher.event_name, self._juju_context)
  File "/var/lib/juju/agents/unit-postgresql-test-app-0/charm/venv/ops/main.py", line 139, in _emit_charm_event
    event_to_emit.emit(*args, **kwargs)
  File "/var/lib/juju/agents/unit-postgresql-test-app-0/charm/venv/ops/framework.py", line 347, in emit
    framework._emit(event)
  File "/var/lib/juju/agents/unit-postgresql-test-app-0/charm/venv/ops/framework.py", line 853, in _emit
    self._reemit(event_path)
  File "/var/lib/juju/agents/unit-postgresql-test-app-0/charm/venv/ops/framework.py", line 943, in _reemit
    custom_handler(event)
  File "/var/lib/juju/agents/unit-postgresql-test-app-0/charm/./src/charm.py", line 289, in _on_clear_continuous_writes_action
    if self._connection_string is None:
  File "/var/lib/juju/agents/unit-postgresql-test-app-0/charm/./src/charm.py", line 259, in _connection_string
    data = list(self.first_database.fetch_relation_data().values())[0]
AttributeError: 'ApplicationCharm' object has no attribute 'first_database'
unit-postgresql-test-app-0: 01:54:44 ERROR unit.postgresql-test-app/0.juju-log Uncaught exception while in charm code:
Traceback (most recent call last):
  File "/var/lib/juju/agents/unit-postgresql-test-app-0/charm/./src/charm.py", line 538, in <module>
    main(ApplicationCharm)
  File "/var/lib/juju/agents/unit-postgresql-test-app-0/charm/venv/ops/main.py", line 553, in main
    manager.run()
  File "/var/lib/juju/agents/unit-postgresql-test-app-0/charm/venv/ops/main.py", line 529, in run
    self._emit()
  File "/var/lib/juju/agents/unit-postgresql-test-app-0/charm/venv/ops/main.py", line 518, in _emit
    _emit_charm_event(self.charm, self.dispatcher.event_name, self._juju_context)
  File "/var/lib/juju/agents/unit-postgresql-test-app-0/charm/venv/ops/main.py", line 139, in _emit_charm_event
    event_to_emit.emit(*args, **kwargs)
  File "/var/lib/juju/agents/unit-postgresql-test-app-0/charm/venv/ops/framework.py", line 347, in emit
    framework._emit(event)
  File "/var/lib/juju/agents/unit-postgresql-test-app-0/charm/venv/ops/framework.py", line 853, in _emit
    self._reemit(event_path)
  File "/var/lib/juju/agents/unit-postgresql-test-app-0/charm/venv/ops/framework.py", line 943, in _reemit
    custom_handler(event)
  File "/var/lib/juju/agents/unit-postgresql-test-app-0/charm/./src/charm.py", line 289, in _on_clear_continuous_writes_action
    if self._connection_string is None:
  File "/var/lib/juju/agents/unit-postgresql-test-app-0/charm/./src/charm.py", line 259, in _connection_string
    data = list(self.first_database.fetch_relation_data().values())[0]
AttributeError: 'ApplicationCharm' object has no attribute 'first_database'
unit-postgresql-test-app-0: 01:54:48 ERROR unit.postgresql-test-app/0.juju-log Uncaught exception while in charm code:
Traceback (most recent call last):
  File "/var/lib/juju/agents/unit-postgresql-test-app-0/charm/./src/charm.py", line 538, in <module>
    main(ApplicationCharm)
  File "/var/lib/juju/agents/unit-postgresql-test-app-0/charm/venv/ops/main.py", line 553, in main
    manager.run()
  File "/var/lib/juju/agents/unit-postgresql-test-app-0/charm/venv/ops/main.py", line 529, in run
    self._emit()
  File "/var/lib/juju/agents/unit-postgresql-test-app-0/charm/venv/ops/main.py", line 518, in _emit
    _emit_charm_event(self.charm, self.dispatcher.event_name, self._juju_context)
  File "/var/lib/juju/agents/unit-postgresql-test-app-0/charm/venv/ops/main.py", line 139, in _emit_charm_event
    event_to_emit.emit(*args, **kwargs)
  File "/var/lib/juju/agents/unit-postgresql-test-app-0/charm/venv/ops/framework.py", line 347, in emit
    framework._emit(event)
  File "/var/lib/juju/agents/unit-postgresql-test-app-0/charm/venv/ops/framework.py", line 853, in _emit
    self._reemit(event_path)
  File "/var/lib/juju/agents/unit-postgresql-test-app-0/charm/venv/ops/framework.py", line 943, in _reemit
    custom_handler(event)
  File "/var/lib/juju/agents/unit-postgresql-test-app-0/charm/./src/charm.py", line 289, in _on_clear_continuous_writes_action
    if self._connection_string is None:
  File "/var/lib/juju/agents/unit-postgresql-test-app-0/charm/./src/charm.py", line 259, in _connection_string
    data = list(self.first_database.fetch_relation_data().values())[0]
AttributeError: 'ApplicationCharm' object has no attribute 'first_database'
unit-postgresql-test-app-0: 01:54:52 ERROR unit.postgresql-test-app/0.juju-log Uncaught exception while in charm code:
Traceback (most recent call last):
  File "/var/lib/juju/agents/unit-postgresql-test-app-0/charm/./src/charm.py", line 538, in <module>
    main(ApplicationCharm)
  File "/var/lib/juju/agents/unit-postgresql-test-app-0/charm/venv/ops/main.py", line 553, in main
    manager.run()
  File "/var/lib/juju/agents/unit-postgresql-test-app-0/charm/venv/ops/main.py", line 529, in run
    self._emit()
  File "/var/lib/juju/agents/unit-postgresql-test-app-0/charm/venv/ops/main.py", line 518, in _emit
    _emit_charm_event(self.charm, self.dispatcher.event_name, self._juju_context)
  File "/var/lib/juju/agents/unit-postgresql-test-app-0/charm/venv/ops/main.py", line 139, in _emit_charm_event
    event_to_emit.emit(*args, **kwargs)
  File "/var/lib/juju/agents/unit-postgresql-test-app-0/charm/venv/ops/framework.py", line 347, in emit
    framework._emit(event)
  File "/var/lib/juju/agents/unit-postgresql-test-app-0/charm/venv/ops/framework.py", line 853, in _emit
    self._reemit(event_path)
  File "/var/lib/juju/agents/unit-postgresql-test-app-0/charm/venv/ops/framework.py", line 943, in _reemit
    custom_handler(event)
  File "/var/lib/juju/agents/unit-postgresql-test-app-0/charm/./src/charm.py", line 289, in _on_clear_continuous_writes_action
    if self._connection_string is None:
  File "/var/lib/juju/agents/unit-postgresql-test-app-0/charm/./src/charm.py", line 259, in _connection_string
    data = list(self.first_database.fetch_relation_data().values())[0]
AttributeError: 'ApplicationCharm' object has no attribute 'first_database'
unit-postgresql-test-app-0: 01:54:56 ERROR unit.postgresql-test-app/0.juju-log Uncaught exception while in charm code:
Traceback (most recent call last):
  File "/var/lib/juju/agents/unit-postgresql-test-app-0/charm/./src/charm.py", line 538, in <module>
    main(ApplicationCharm)
  File "/var/lib/juju/agents/unit-postgresql-test-app-0/charm/venv/ops/main.py", line 553, in main
    manager.run()
  File "/var/lib/juju/agents/unit-postgresql-test-app-0/charm/venv/ops/main.py", line 529, in run
    self._emit()
  File "/var/lib/juju/agents/unit-postgresql-test-app-0/charm/venv/ops/main.py", line 518, in _emit
    _emit_charm_event(self.charm, self.dispatcher.event_name, self._juju_context)
  File "/var/lib/juju/agents/unit-postgresql-test-app-0/charm/venv/ops/main.py", line 139, in _emit_charm_event
    event_to_emit.emit(*args, **kwargs)
  File "/var/lib/juju/agents/unit-postgresql-test-app-0/charm/venv/ops/framework.py", line 347, in emit
    framework._emit(event)
  File "/var/lib/juju/agents/unit-postgresql-test-app-0/charm/venv/ops/framework.py", line 853, in _emit
    self._reemit(event_path)
  File "/var/lib/juju/agents/unit-postgresql-test-app-0/charm/venv/ops/framework.py", line 943, in _reemit
    custom_handler(event)
  File "/var/lib/juju/agents/unit-postgresql-test-app-0/charm/./src/charm.py", line 289, in _on_clear_continuous_writes_action
    if self._connection_string is None:
  File "/var/lib/juju/agents/unit-postgresql-test-app-0/charm/./src/charm.py", line 259, in _connection_string
    data = list(self.first_database.fetch_relation_data().values())[0]
AttributeError: 'ApplicationCharm' object has no attribute 'first_database'
unit-postgresql-test-app-0: 01:55:00 ERROR unit.postgresql-test-app/0.juju-log Uncaught exception while in charm code:
Traceback (most recent call last):
  File "/var/lib/juju/agents/unit-postgresql-test-app-0/charm/./src/charm.py", line 538, in <module>
    main(ApplicationCharm)
  File "/var/lib/juju/agents/unit-postgresql-test-app-0/charm/venv/ops/main.py", line 553, in main
    manager.run()
  File "/var/lib/juju/agents/unit-postgresql-test-app-0/charm/venv/ops/main.py", line 529, in run
    self._emit()
  File "/var/lib/juju/agents/unit-postgresql-test-app-0/charm/venv/ops/main.py", line 518, in _emit
    _emit_charm_event(self.charm, self.dispatcher.event_name, self._juju_context)
  File "/var/lib/juju/agents/unit-postgresql-test-app-0/charm/venv/ops/main.py", line 139, in _emit_charm_event
    event_to_emit.emit(*args, **kwargs)
  File "/var/lib/juju/agents/unit-postgresql-test-app-0/charm/venv/ops/framework.py", line 347, in emit
    framework._emit(event)
  File "/var/lib/juju/agents/unit-postgresql-test-app-0/charm/venv/ops/framework.py", line 853, in _emit
    self._reemit(event_path)
  File "/var/lib/juju/agents/unit-postgresql-test-app-0/charm/venv/ops/framework.py", line 943, in _reemit
    custom_handler(event)
  File "/var/lib/juju/agents/unit-postgresql-test-app-0/charm/./src/charm.py", line 289, in _on_clear_continuous_writes_action
    if self._connection_string is None:
  File "/var/lib/juju/agents/unit-postgresql-test-app-0/charm/./src/charm.py", line 259, in _connection_string
    data = list(self.first_database.fetch_relation_data().values())[0]
AttributeError: 'ApplicationCharm' object has no attribute 'first_database'
unit-postgresql-test-app-0: 01:55:04 ERROR unit.postgresql-test-app/0.juju-log Uncaught exception while in charm code:
Traceback (most recent call last):
  File "/var/lib/juju/agents/unit-postgresql-test-app-0/charm/./src/charm.py", line 538, in <module>
    main(ApplicationCharm)
  File "/var/lib/juju/agents/unit-postgresql-test-app-0/charm/venv/ops/main.py", line 553, in main
    manager.run()
  File "/var/lib/juju/agents/unit-postgresql-test-app-0/charm/venv/ops/main.py", line 529, in run
    self._emit()
  File "/var/lib/juju/agents/unit-postgresql-test-app-0/charm/venv/ops/main.py", line 518, in _emit
    _emit_charm_event(self.charm, self.dispatcher.event_name, self._juju_context)
  File "/var/lib/juju/agents/unit-postgresql-test-app-0/charm/venv/ops/main.py", line 139, in _emit_charm_event
    event_to_emit.emit(*args, **kwargs)
  File "/var/lib/juju/agents/unit-postgresql-test-app-0/charm/venv/ops/framework.py", line 347, in emit
    framework._emit(event)
  File "/var/lib/juju/agents/unit-postgresql-test-app-0/charm/venv/ops/framework.py", line 853, in _emit
    self._reemit(event_path)
  File "/var/lib/juju/agents/unit-postgresql-test-app-0/charm/venv/ops/framework.py", line 943, in _reemit
    custom_handler(event)
  File "/var/lib/juju/agents/unit-postgresql-test-app-0/charm/./src/charm.py", line 289, in _on_clear_continuous_writes_action
    if self._connection_string is None:
  File "/var/lib/juju/agents/unit-postgresql-test-app-0/charm/./src/charm.py", line 259, in _connection_string
    data = list(self.first_database.fetch_relation_data().values())[0]
AttributeError: 'ApplicationCharm' object has no attribute 'first_database'
unit-postgresql-test-app-0: 01:55:08 ERROR unit.postgresql-test-app/0.juju-log Uncaught exception while in charm code:
Traceback (most recent call last):
  File "/var/lib/juju/agents/unit-postgresql-test-app-0/charm/./src/charm.py", line 538, in <module>
    main(ApplicationCharm)
  File "/var/lib/juju/agents/unit-postgresql-test-app-0/charm/venv/ops/main.py", line 553, in main
    manager.run()
  File "/var/lib/juju/agents/unit-postgresql-test-app-0/charm/venv/ops/main.py", line 529, in run
    self._emit()
  File "/var/lib/juju/agents/unit-postgresql-test-app-0/charm/venv/ops/main.py", line 518, in _emit
    _emit_charm_event(self.charm, self.dispatcher.event_name, self._juju_context)
  File "/var/lib/juju/agents/unit-postgresql-test-app-0/charm/venv/ops/main.py", line 139, in _emit_charm_event
    event_to_emit.emit(*args, **kwargs)
  File "/var/lib/juju/agents/unit-postgresql-test-app-0/charm/venv/ops/framework.py", line 347, in emit
    framework._emit(event)
  File "/var/lib/juju/agents/unit-postgresql-test-app-0/charm/venv/ops/framework.py", line 853, in _emit
    self._reemit(event_path)
  File "/var/lib/juju/agents/unit-postgresql-test-app-0/charm/venv/ops/framework.py", line 943, in _reemit
    custom_handler(event)
  File "/var/lib/juju/agents/unit-postgresql-test-app-0/charm/./src/charm.py", line 289, in _on_clear_continuous_writes_action
    if self._connection_string is None:
  File "/var/lib/juju/agents/unit-postgresql-test-app-0/charm/./src/charm.py", line 259, in _connection_string
    data = list(self.first_database.fetch_relation_data().values())[0]
AttributeError: 'ApplicationCharm' object has no attribute 'first_database'
unit-postgresql-test-app-0: 01:55:12 ERROR unit.postgresql-test-app/0.juju-log Uncaught exception while in charm code:
Traceback (most recent call last):
  File "/var/lib/juju/agents/unit-postgresql-test-app-0/charm/./src/charm.py", line 538, in <module>
    main(ApplicationCharm)
  File "/var/lib/juju/agents/unit-postgresql-test-app-0/charm/venv/ops/main.py", line 553, in main
    manager.run()
  File "/var/lib/juju/agents/unit-postgresql-test-app-0/charm/venv/ops/main.py", line 529, in run
    self._emit()
  File "/var/lib/juju/agents/unit-postgresql-test-app-0/charm/venv/ops/main.py", line 518, in _emit
    _emit_charm_event(self.charm, self.dispatcher.event_name, self._juju_context)
  File "/var/lib/juju/agents/unit-postgresql-test-app-0/charm/venv/ops/main.py", line 139, in _emit_charm_event
    event_to_emit.emit(*args, **kwargs)
  File "/var/lib/juju/agents/unit-postgresql-test-app-0/charm/venv/ops/framework.py", line 347, in emit
    framework._emit(event)
  File "/var/lib/juju/agents/unit-postgresql-test-app-0/charm/venv/ops/framework.py", line 853, in _emit
    self._reemit(event_path)
  File "/var/lib/juju/agents/unit-postgresql-test-app-0/charm/venv/ops/framework.py", line 943, in _reemit
    custom_handler(event)
  File "/var/lib/juju/agents/unit-postgresql-test-app-0/charm/./src/charm.py", line 289, in _on_clear_continuous_writes_action
    if self._connection_string is None:
  File "/var/lib/juju/agents/unit-postgresql-test-app-0/charm/./src/charm.py", line 259, in _connection_string
    data = list(self.first_database.fetch_relation_data().values())[0]
AttributeError: 'ApplicationCharm' object has no attribute 'first_database'
unit-postgresql-test-app-0: 01:55:16 ERROR unit.postgresql-test-app/0.juju-log Uncaught exception while in charm code:
Traceback (most recent call last):
  File "/var/lib/juju/agents/unit-postgresql-test-app-0/charm/./src/charm.py", line 538, in <module>
    main(ApplicationCharm)
  File "/var/lib/juju/agents/unit-postgresql-test-app-0/charm/venv/ops/main.py", line 553, in main
    manager.run()
  File "/var/lib/juju/agents/unit-postgresql-test-app-0/charm/venv/ops/main.py", line 529, in run
    self._emit()
  File "/var/lib/juju/agents/unit-postgresql-test-app-0/charm/venv/ops/main.py", line 518, in _emit
    _emit_charm_event(self.charm, self.dispatcher.event_name, self._juju_context)
  File "/var/lib/juju/agents/unit-postgresql-test-app-0/charm/venv/ops/main.py", line 139, in _emit_charm_event
    event_to_emit.emit(*args, **kwargs)
  File "/var/lib/juju/agents/unit-postgresql-test-app-0/charm/venv/ops/framework.py", line 347, in emit
    framework._emit(event)
  File "/var/lib/juju/agents/unit-postgresql-test-app-0/charm/venv/ops/framework.py", line 853, in _emit
    self._reemit(event_path)
  File "/var/lib/juju/agents/unit-postgresql-test-app-0/charm/venv/ops/framework.py", line 943, in _reemit
    custom_handler(event)
  File "/var/lib/juju/agents/unit-postgresql-test-app-0/charm/./src/charm.py", line 289, in _on_clear_continuous_writes_action
    if self._connection_string is None:
  File "/var/lib/juju/agents/unit-postgresql-test-app-0/charm/./src/charm.py", line 259, in _connection_string
    data = list(self.first_database.fetch_relation_data().values())[0]
AttributeError: 'ApplicationCharm' object has no attribute 'first_database'
unit-postgresql-test-app-0: 01:55:20 ERROR unit.postgresql-test-app/0.juju-log Uncaught exception while in charm code:
Traceback (most recent call last):
  File "/var/lib/juju/agents/unit-postgresql-test-app-0/charm/./src/charm.py", line 538, in <module>
    main(ApplicationCharm)
  File "/var/lib/juju/agents/unit-postgresql-test-app-0/charm/venv/ops/main.py", line 553, in main
    manager.run()
  File "/var/lib/juju/agents/unit-postgresql-test-app-0/charm/venv/ops/main.py", line 529, in run
    self._emit()
  File "/var/lib/juju/agents/unit-postgresql-test-app-0/charm/venv/ops/main.py", line 518, in _emit
    _emit_charm_event(self.charm, self.dispatcher.event_name, self._juju_context)
  File "/var/lib/juju/agents/unit-postgresql-test-app-0/charm/venv/ops/main.py", line 139, in _emit_charm_event
    event_to_emit.emit(*args, **kwargs)
  File "/var/lib/juju/agents/unit-postgresql-test-app-0/charm/venv/ops/framework.py", line 347, in emit
    framework._emit(event)
  File "/var/lib/juju/agents/unit-postgresql-test-app-0/charm/venv/ops/framework.py", line 853, in _emit
    self._reemit(event_path)
  File "/var/lib/juju/agents/unit-postgresql-test-app-0/charm/venv/ops/framework.py", line 943, in _reemit
    custom_handler(event)
  File "/var/lib/juju/agents/unit-postgresql-test-app-0/charm/./src/charm.py", line 289, in _on_clear_continuous_writes_action
    if self._connection_string is None:
  File "/var/lib/juju/agents/unit-postgresql-test-app-0/charm/./src/charm.py", line 259, in _connection_string
    data = list(self.first_database.fetch_relation_data().values())[0]
AttributeError: 'ApplicationCharm' object has no attribute 'first_database'
unit-postgresql-test-app-0: 01:55:24 ERROR unit.postgresql-test-app/0.juju-log Uncaught exception while in charm code:
Traceback (most recent call last):
  File "/var/lib/juju/agents/unit-postgresql-test-app-0/charm/./src/charm.py", line 538, in <module>
    main(ApplicationCharm)
  File "/var/lib/juju/agents/unit-postgresql-test-app-0/charm/venv/ops/main.py", line 553, in main
    manager.run()
  File "/var/lib/juju/agents/unit-postgresql-test-app-0/charm/venv/ops/main.py", line 529, in run
    self._emit()
  File "/var/lib/juju/agents/unit-postgresql-test-app-0/charm/venv/ops/main.py", line 518, in _emit
    _emit_charm_event(self.charm, self.dispatcher.event_name, self._juju_context)
  File "/var/lib/juju/agents/unit-postgresql-test-app-0/charm/venv/ops/main.py", line 139, in _emit_charm_event
    event_to_emit.emit(*args, **kwargs)
  File "/var/lib/juju/agents/unit-postgresql-test-app-0/charm/venv/ops/framework.py", line 347, in emit
    framework._emit(event)
  File "/var/lib/juju/agents/unit-postgresql-test-app-0/charm/venv/ops/framework.py", line 853, in _emit
    self._reemit(event_path)
  File "/var/lib/juju/agents/unit-postgresql-test-app-0/charm/venv/ops/framework.py", line 943, in _reemit
    custom_handler(event)
  File "/var/lib/juju/agents/unit-postgresql-test-app-0/charm/./src/charm.py", line 289, in _on_clear_continuous_writes_action
    if self._connection_string is None:
  File "/var/lib/juju/agents/unit-postgresql-test-app-0/charm/./src/charm.py", line 259, in _connection_string
    data = list(self.first_database.fetch_relation_data().values())[0]
AttributeError: 'ApplicationCharm' object has no attribute 'first_database'

[32mINFO    [0m pytest_operator.plugin:plugin.py:947 Forgetting model main...